Workbook

Sheet PREÇOS
A1: CATEGORIA | B1: PRODUTO | C1: VALOR UNITÁRIO | E1: ⚠️ ALTERE OS VALORES AQUI - ATUALIZA TODAS AS ABAS AUTOMATICAMENTE
A2: PÃES SALGADOS | B2: Mini Pão Francês | C2: 0.4
A3: PÃES SALGADOS | B3: Mini Pão Integral | C3: 0.6
A4: PÃES SALGADOS | B4: Mini Australiano | C4: 0.8
A5: PÃES SALGADOS | B5: Mini Pão Gergilim | C5: 0.45
A6: PÃES SALGADOS | B6: Mini Pão de Milho ou | C6: 0.45
A7: PÃES SALGADOS | B7: Mini Baguete Rustica | C7: 0.65
A8: PÃES SALGADOS | B8: Mini Pão Calabresa | C8: 0.8
A9: PÃES SALGADOS | B9: Mini Pão Delicia recheado | C9: 0.7
A10: PÃES SALGADOS | B10: Focaccia recheada | C10: 1.55
A11: PÃES SALGADOS | B11: Mini Tiger | C11: 0.4
A12: PÃES SALGADOS | B12: Mini Pão de Frios | C12: 0.8
A13: PÃES SALGADOS | B13: Pão de Forma integral | C13: 3
... A32: REFEITÓRIO | B32: Pão de leite 50g | C32: 0.8

Sheet DIA 1
A1: HOTEL NANNAI MURO ALTO
A2: PADARIA / CONFEITARIA
A4: PRODUÇÃO | B4: Dia: 01/06/2026
A5: RESTAURANTE NANNAI
A6: PAX | D6: PADARIA | F6: ATENÇÃO ALTERAR SOMENTE EM VERMELHO, ALTERAR SOMENTE O NUMERO DE PESSOAS PAX
A8: unidades | B8: VALOR | C8: TOTAL | D8: PÃES SALGADOS
A9: =$C$6*0.9 -> 0 | B9: =IFERROR(VLOOKUP(D9,PREÇOS!$B$2:$C$32,2,FALSE),0) -> 0.4 | C9: =$A$9*$B$9 -> 0 | D9: Mini Pão Francês
A10: =$C$6*0.2 -> 0 | B10: =IFERROR(VLOOKUP(D10,PREÇOS!$B$2:$C$32,2,FALSE),0) -> 0.6 | C10: =$A$10*$B$10 -> 0 | D10: Mini Pão Integral
A11: =$C$6*0.2 -> 0 | B11: =IFERROR(VLOOKUP(D11,PREÇOS!$B$2:$C$32,2,FALSE),0) -> 0.8 | C11: =$A$11*$B$11 -> 0 | D11: Mini Australiano
A12: =$C$6*0.2 -> 0 | B12: =IFERROR(VLOOKUP(D12,PREÇOS!$B$2:$C$32,2,FALSE),0) -> 0.45 | C12: =$A$12*$B$12 -> 0 | D12: Mini Pão Gergilim
A13: =$C$6*0.2 -> 0 | B13: =IFERROR(VLOOKUP(D13,PREÇOS!$B$2:$C$32,2,FALSE),0) -> 0 | C13: =$A$13*$B$13 -> 0 | D13: Mini Pão de Milho ou
A14: =$C$6*0.1 -> 0 | B14: =IFERROR(VLOOKUP(D14,PREÇOS!$B$2:$C$32,2,FALSE),0) -> 0 | C14: =$A$14*$B$14 -> 0 | D14: Mini Baguete Rustica
A15: =$C$6*0.2 -> 0 | B15: =IFERROR(VLOOKUP(D15,PREÇOS!$B$2:$C$32,2,FALSE),0) -> 0.8 | C15: =$A$15*$B$15 -> 0 | D15: Mini Pão Calabresa
A16: =$C$6*0.2 -> 0 | B16: =IFERROR(VLOOKUP(D16,PREÇOS!$B$2:$C$32,2,FALSE),0) -> 0.7 | C16: =$A$16*$B$16 -> 0 | D16: Mini Pão Delicia recheado
A17: =$C$6*0.01 -> 0 | B17: =IFERROR(VLOOKUP(D17,PREÇOS!$B$2:$C$32,2,FALSE),0) -> 1.55 | C17: =$A$17*$B$17 -> 0 | D17: Focaccia recheada
A18: =$C$6*0.3 -> 0 | B18: =IFERROR(VLOOKUP(D18,PREÇOS!$B$2:$C$32,2,FALSE),0) -> 0.4 | C18: =$A$18*$B$18 -> 0 | D18: Mini Tiger
A19: =$C$6*0.2 -> 0 | B19: =IFERROR(VLOOKUP(D19,PREÇOS!$B$2:$C$32,2,FALSE),0) -> 0.8 | C19: =$A$19*$B$19 -> 0 | D19: Mini Pão de Frios
A20: =$C$6*0.004 -> 0 | B20: =IFERROR(VLOOKUP(D20,PREÇOS!$B$2:$C$32,2,FALSE),0) -> 3 | C20: =$A$20*$B$20 -> 0 | D20: Pão de Forma integral
A21: =$C$6*0.009 -> 0 | B21: =IFERROR(VLOOKUP(D21,PREÇOS!$B$2:$C$32,2,FALSE),0) -> 2.8 | C21: =$A$21*$B$21 -> 0 | D21: Pão de forma Tradicional
A22: =$C$6*0.004 -> 0 | B22: =IFERROR(VLOOKUP(D22,PREÇOS!$B$2:$C$32,2,FALSE),0) -> 3 | C22: =$A$22*$B$22 -> 0 | D22: Pão de Forma Maritoso
A23: =$C$6*0.04 -> 0 | B23: =IFERROR(VLOOKUP(D23,PREÇOS!$B$2:$C$32,2,FALSE),0) -> 2.6 | C23: =$A$23*$B$23 -> 0 | D23: Baguete Francesa 300g
A24: =$C$6*0.04 -> 0 | B24: =IFERROR(VLOOKUP(D24,PREÇOS!$B$2:$C$32,2,FALSE),0) -> 3.8 | C24: =$A$24*$B$24 -> 0 | D24: Pães de Decoração Rustico
D25: PÃES DOCES
A26: =$C$6*0.2 -> 0 | B26: =IFERROR(VLOOKUP(D26,PREÇOS!$B$2:$C$32,2,FALSE),0) -> 0.6 | C26: =$A$26*$B$26 -> 0 | D26: Mini Brioche ou Pão de Açucar
A27: =$C$6*0.2 -> 0 | B27: =IFERROR(VLOOKUP(D27,PREÇOS!$B$2:$C$32,2,FALSE),0) -> 0.5 | C27: =$A$27*$B$27 -> 0 | D27: Mini Bisnaguinha
A28: =$C$6*0.1 -> 0 | B28: =IFERROR(VLOOKUP(D28,PREÇOS!$B$2:$C$32,2,FALSE),0) -> 0.75 | C28: =$A$28*$B$28 -> 0 | D28: Mini Pão de coco
A29: =$C$6*0.1 -> 0 | B29: =IFERROR(VLOOKUP(D29,PREÇOS!$B$2:$C$32,2,FALSE),0) -> 0.6 | C29: =$A$29*$B$29 -> 0 | D29: Mini Pão doce
A30: =$C$6*0.2 -> 0 | B30: =IFERROR(VLOOKUP(D30,PREÇOS!$B$2:$C$32,2,FALSE),0) -> 0.8 | C30: =$A$30*$B$30 -> 0 | D30: Mini Donuts
A31: =$C$6*0.2 -> 0 | B31: =IFERROR(VLOOKUP(D31,PREÇOS!$B$2:$C$32,2,FALSE),0) -> 0.8 | C31: =$A$31*$B$31 -> 0 | D31: Mini Sonho
A32: =$C$6*0.2 -> 0 | B32: =IFERROR(VLOOKUP(D32,PREÇOS!$B$2:$C$32,2,FALSE),0) -> 0.85 | C32: =$A$32*$B$32 -> 0 | D32: Mini cookies
D33: FOLHADOS
A34: =$C$6*0.7 -> 0 | B34: =IFERROR(VLOOKUP(D34,PREÇOS!$B$2:$C$32,2,FALSE),0) -> 1.6 | C34: =$A$34*$B$34 -> 0 | D34: Mini Croissant
A35: =$C$6*0.5 -> 0 | B35: =IFERROR(VLOOKUP(D35,PREÇOS!$B$2:$C$32,2,FALSE),0) -> 1.8 | C35: =$A$35*$B$35 -> 0 | D35: Mini Pão de Chocolate
A36: =$C$6*0.5 -> 0 | B36: =IFERROR(VLOOKUP(D36,PREÇOS!$B$2:$C$32,2,FALSE),0) -> 0.95 | C36: =$A$36*$B$36 -> 0 | D36: Mini Folhado Salgado
A38: Total: | C38: =SUM(C9:C37) -> 0
A40: Produtos Volantes
A41: PAX | C41: 0 | D41: PADARIA
A42: unidades | D42: Pães salgados e doces
A43: =$C$41*0.7 -> 0 | B43: =IFERROR(VLOOKUP(D43,PREÇOS!$B$2:$C$32,2,FALSE),0) -> 0.63 | C43: =$A$43*$B$43 -> 0 | D43: Pão de queijo
A44: =$C$41*0.3 -> 0 | B44: =IFERROR(VLOOKUP(D44,PREÇOS!$B$2:$C$32,2,FALSE),0) -> 0.95 | C44: =$A$44*$B$44 -> 0 | D44: Folhado Salgado
...

Sheet DIA 2
A1: HOTEL NANNAI MURO ALTO
A2: PADARIA / CONFEITARIA
A4: PRODUÇÃO | B4: Dia: 02/06/2026
A5: RESTAURANTE NANNAI
A6: PAX | C6: 0 | D6: PADARIA | F6: ATENÇÃO ALTERAR SOMENTE EM VERMELHO, ALTERAR SOMENTE O NUMERO DE PESSOAS PAX
A8: unidades | B8: VALOR | C8: TOTAL | D8: PÃES SALGADOS
A9: =$C$6*0.9 -> 0 | B9: =IFERROR(VLOOKUP(D9,PREÇOS!$B$2:$C$32,2,FALSE),0) -> 0.4 | C9: =$A$9*$B$9 -> 0 | D9: Mini Pão Francês
A10: =$C$6*0.2 -> 0 | B10: =IFERROR(VLOOKUP(D10,PREÇOS!$B$2:$C$32,2,FALSE),0) -> 0.6 | C10: =$A$10*$B$10 -> 0 | D10: Mini Pão Integral
A11: =$C$6*0.2 -> 0 | B11: =IFERROR(VLOOKUP(D11,PREÇOS!$B$2:$C$32,2,FALSE),0) -> 0.8 | C11: =$A$11*$B$11 -> 0 | D11: Mini Australiano
A12: =$C$6*0.2 -> 0 | B12: =IFERROR(VLOOKUP(D12,PREÇOS!$B$2:$C$32,2,FALSE),0) -> 0.45 | C12: =$A$12*$B$12 -> 0 | D12: Mini Pão Gergilim
A13: =$C$6*0.2 -> 0 | B13: =IFERROR(VLOOKUP(D13,PREÇOS!$B$2:$C$32,2,FALSE),0) -> 0 | C13: =$A$13*$B$13 -> 0 | D13: Mini Pão de Milho ou
A14: =$C$6*0.1 -> 0 | B14: =IFERROR(VLOOKUP(D14,PREÇOS!$B$2:$C$32,2,FALSE),0) -> 0 | C14: =$A$14*$B$14 -> 0 | D14: Mini Baguete Rustica
A15: =$C$6*0.2 -> 0 | B15: =IFERROR(VLOOKUP(D15,PREÇOS!$B$2:$C$32,2,FALSE),0) -> 0.8 | C15: =$A$15*$B$15 -> 0 | D15: Mini Pão Calabresa
A16: =$C$6*0.2 -> 0 | B16: =IFERROR(VLOOKUP(D16,PREÇOS!$B$2:$C$32,2,FALSE),0) -> 0.7 | C16: =$A$16*$B$16 -> 0 | D16: Mini Pão Delicia recheado
A17: =$C$6*0.01 -> 0 | B17: =IFERROR(VLOOKUP(D17,PREÇOS!$B$2:$C$32,2,FALSE),0) -> 1.55 | C17: =$A$17*$B$17 -> 0 | D17: Focaccia recheada
A18: =$C$6*0.3 -> 0 | B18: =IFERROR(VLOOKUP(D18,PREÇOS!$B$2:$C$32,2,FALSE),0) -> 0.4 | C18: =$A$18*$B$18 -> 0 | D18: Mini Tiger
A19: =$C$6*0.2 -> 0 | B19: =IFERROR(VLOOKUP(D19,PREÇOS!$B$2:$C$32,2,FALSE),0) -> 0.8 | C19: =$A$19*$B$19 -> 0 | D19: Mini Pão de Frios
A20: =$C$6*0.004 -> 0 | B20: =IFERROR(VLOOKUP(D20,PREÇOS!$B$2:$C$32,2,FALSE),0) -> 3 | C20: =$A$20*$B$20 -> 0 | D20: Pão de Forma integral
A21: =$C$6*0.009 -> 0 | B21: =IFERROR(VLOOKUP(D21,PREÇOS!$B$2:$C$32,2,FALSE),0) -> 2.8 | C21: =$A$21*$B$21 -> 0 | D21: Pão de forma Tradicional
A22: =$C$6*0.004 -> 0 | B22: =IFERROR(VLOOKUP(D22,PREÇOS!$B$2:$C$32,2,FALSE),0) -> 3 | C22: =$A$22*$B$22 -> 0 | D22: Pão de Forma Maritoso
A23: =$C$6*0.04 -> 0 | B23: =IFERROR(VLOOKUP(D23,PREÇOS!$B$2:$C$32,2,FALSE),0) -> 2.6 | C23: =$A$23*$B$23 -> 0 | D23: Baguete Francesa 300g
A24: =$C$6*0.04 -> 0 | B24: =IFERROR(VLOOKUP(D24,PREÇOS!$B$2:$C$32,2,FALSE),0) -> 3.8 | C24: =$A$24*$B$24 -> 0 | D24: Pães de Decoração Rustico
D25: PÃES DOCES
A26: =$C$6*0.2 -> 0 | B26: =IFERROR(VLOOKUP(D26,PREÇOS!$B$2:$C$32,2,FALSE),0) -> 0.6 | C26: =$A$26*$B$26 -> 0 | D26: Mini Brioche ou Pão de Açucar
A27: =$C$6*0.2 -> 0 | B27: =IFERROR(VLOOKUP(D27,PREÇOS!$B$2:$C$32,2,FALSE),0) -> 0.5 | C27: =$A$27*$B$27 -> 0 | D27: Mini Bisnaguinha
A28: =$C$6*0.1 -> 0 | B28: =IFERROR(VLOOKUP(D28,PREÇOS!$B$2:$C$32,2,FALSE),0) -> 0.75 | C28: =$A$28*$B$28 -> 0 | D28: Mini Pão de coco
A29: =$C$6*0.1 -> 0 | B29: =IFERROR(VLOOKUP(D29,PREÇOS!$B$2:$C$32,2,FALSE),0) -> 0.6 | C29: =$A$29*$B$29 -> 0 | D29: Mini Pão doce
A30: =$C$6*0.2 -> 0 | B30: =IFERROR(VLOOKUP(D30,PREÇOS!$B$2:$C$32,2,FALSE),0) -> 0.8 | C30: =$A$30*$B$30 -> 0 | D30: Mini Donuts
A31: =$C$6*0.2 -> 0 | B31: =IFERROR(VLOOKUP(D31,PREÇOS!$B$2:$C$32,2,FALSE),0) -> 0.8 | C31: =$A$31*$B$31 -> 0 | D31: Mini Sonho
A32: =$C$6*0.2 -> 0 | B32: =IFERROR(VLOOKUP(D32,PREÇOS!$B$2:$C$32,2,FALSE),0) -> 0.85 | C32: =$A$32*$B$32 -> 0 | D32: Mini cookies
D33: FOLHADOS
A34: =$C$6*0.7 -> 0 | B34: =IFERROR(VLOOKUP(D34,PREÇOS!$B$2:$C$32,2,FALSE),0) -> 1.6 | C34: =$A$34*$B$34 -> 0 | D34: Mini Croissant
A35: =$C$6*0.5 -> 0 | B35: =IFERROR(VLOOKUP(D35,PREÇOS!$B$2:$C$32,2,FALSE),0) -> 1.8 | C35: =$A$35*$B$35 -> 0 | D35: Mini Pão de Chocolate
A36: =$C$6*0.5 -> 0 | B36: =IFERROR(VLOOKUP(D36,PREÇOS!$B$2:$C$32,2,FALSE),0) -> 0.95 | C36: =$A$36*$B$36 -> 0 | D36: Mini Folhado Salgado
A38: Total: | C38: =SUM(C9:C37) -> 0
A40: Produtos Volantes
A41: PAX | C41: 0 | D41: PADARIA
A42: unidades | D42: Pães salgados e doces
A43: =$C$41*0.7 -> 0 | B43: =IFERROR(VLOOKUP(D43,PREÇOS!$B$2:$C$32,2,FALSE),0) -> 0.63 | C43: =$A$43*$B$43 -> 0 | D43: Pão de queijo
A44: =$C$41*0.3 -> 0 | B44: =IFERROR(VLOOKUP(D44,PREÇOS!$B$2:$C$32,2,FALSE),0) -> 0.95 | C44: =$A$44*$B$44 -> 0 | D44: Folhado Salgado
...

Sheet DIA 3
A1: HOTEL NANNAI MURO ALTO
A2: PADARIA / CONFEITARIA
A4: PRODUÇÃO | B4: Dia: 03/06/2026
A5: RESTAURANTE NANNAI
A6: PAX | C6: 0 | D6: PADARIA | F6: ATENÇÃO ALTERAR SOMENTE EM VERMELHO, ALTERAR SOMENTE O NUMERO DE PESSOAS PAX
A8: unidades | B8: VALOR | C8: TOTAL | D8: PÃES SALGADOS
A9: =$C$6*0.9 -> 0 | B9: =IFERROR(VLOOKUP(D9,PREÇOS!$B$2:$C$32,2,FALSE),0) -> 0.4 | C9: =$A$9*$B$9 -> 0 | D9: Mini Pão Francês
A10: =$C$6*0.2 -> 0 | B10: =IFERROR(VLOOKUP(D10,PREÇOS!$B$2:$C$32,2,FALSE),0) -> 0.6 | C10: =$A$10*$B$10 -> 0 | D10: Mini Pão Integral
A11: =$C$6*0.2 -> 0 | B11: =IFERROR(VLOOKUP(D11,PREÇOS!$B$2:$C$32,2,FALSE),0) -> 0.8 | C11: =$A$11*$B$11 -> 0 | D11: Mini Australiano
A12: =$C$6*0.2 -> 0 | B12: =IFERROR(VLOOKUP(D12,PREÇOS!$B$2:$C$32,2,FALSE),0) -> 0.45 | C12: =$A$12*$B$12 -> 0 | D12: Mini Pão Gergilim
A13: =$C$6*0.2 -> 0 | B13: =IFERROR(VLOOKUP(D13,PREÇOS!$B$2:$C$32,2,FALSE),0) -> 0 | C13: =$A$13*$B$13 -> 0 | D13: Mini Pão de Milho ou
A14: =$C$6*0.1 -> 0 | B14: =IFERROR(VLOOKUP(D14,PREÇOS!$B$2:$C$32,2,FALSE),0) -> 0 | C14: =$A$14*$B$14 -> 0 | D14: Mini Baguete Rustica
A15: =$C$6*0.2 -> 0 | B15: =IFERROR(VLOOKUP(D15,PREÇOS!$B$2:$C$32,2,FALSE),0) -> 0.8 | C15: =$A$15*$B$15 -> 0 | D15: Mini Pão Calabresa
A16: =$C$6*0.2 -> 0 | B16: =IFERROR(VLOOKUP(D16,PREÇOS!$B$2:$C$32,2,FALSE),0) -> 0.7 | C16: =$A$16*$B$16 -> 0 | D16: Mini Pão Delicia recheado
A17: =$C$6*0.01 -> 0 | B17: =IFERROR(VLOOKUP(D17,PREÇOS!$B$2:$C$32,2,FALSE),0) -> 1.55 | C17: =$A$17*$B$17 -> 0 | D17: Focaccia recheada
A18: =$C$6*0.3 -> 0 | B18: =IFERROR(VLOOKUP(D18,PREÇOS!$B$2:$C$32,2,FALSE),0) -> 0.4 | C18: =$A$18*$B$18 -> 0 | D18: Mini Tiger
A19: =$C$6*0.2 -> 0 | B19: =IFERROR(VLOOKUP(D19,PREÇOS!$B$2:$C$32,2,FALSE),0) -> 0.8 | C19: =$A$19*$B$19 -> 0 | D19: Mini Pão de Frios
A20: =$C$6*0.004 -> 0 | B20: =IFERROR(VLOOKUP(D20,PREÇOS!$B$2:$C$32,2,FALSE),0) -> 3 | C20: =$A$20*$B$20 -> 0 | D20: Pão de Forma integral
A21: =$C$6*0.009 -> 0 | B21: =IFERROR(VLOOKUP(D21,PREÇOS!$B$2:$C$32,2,FALSE),0) -> 2.8 | C21: =$A$21*$B$21 -> 0 | D21: Pão de forma Tradicional
A22: =$C$6*0.004 -> 0 | B22: =IFERROR(VLOOKUP(D22,PREÇOS!$B$2:$C$32,2,FALSE),0) -> 3 | C22: =$A$22*$B$22 -> 0 | D22: Pão de Forma Maritoso
A23: =$C$6*0.04 -> 0 | B23: =IFERROR(VLOOKUP(D23,PREÇOS!$B$2:$C$32,2,FALSE),0) -> 2.6 | C23: =$A$23*$B$23 -> 0 | D23: Baguete Francesa 300g
A24: =$C$6*0.04 -> 0 | B24: =IFERROR(VLOOKUP(D24,PREÇOS!$B$2:$C$32,2,FALSE),0) -> 3.8 | C24: =$A$24*$B$24 -> 0 | D24: Pães de Decoração Rustico
D25: PÃES DOCES
A26: =$C$6*0.2 -> 0 | B26: =IFERROR(VLOOKUP(D26,PREÇOS!$B$2:$C$32,2,FALSE),0) -> 0.6 | C26: =$A$26*$B$26 -> 0 | D26: Mini Brioche ou Pão de Açucar
A27: =$C$6*0.2 -> 0 | B27: =IFERROR(VLOOKUP(D27,PREÇOS!$B$2:$C$32,2,FALSE),0) -> 0.5 | C27: =$A$27*$B$27 -> 0 | D27: Mini Bisnaguinha
A28: =$C$6*0.1 -> 0 | B28: =IFERROR(VLOOKUP(D28,PREÇOS!$B$2:$C$32,2,FALSE),0) -> 0.75 | C28: =$A$28*$B$28 -> 0 | D28: Mini Pão de coco
A29: =$C$6*0.1 -> 0 | B29: =IFERROR(VLOOKUP(D29,PREÇOS!$B$2:$C$32,2,FALSE),0) -> 0.6 | C29: =$A$29*$B$29 -> 0 | D29: Mini Pão doce
A30: =$C$6*0.2 -> 0 | B30: =IFERROR(VLOOKUP(D30,PREÇOS!$B$2:$C$32,2,FALSE),0) -> 0.8 | C30: =$A$30*$B$30 -> 0 | D30: Mini Donuts
A31: =$C$6*0.2 -> 0 | B31: =IFERROR(VLOOKUP(D31,PREÇOS!$B$2:$C$32,2,FALSE),0) -> 0.8 | C31: =$A$31*$B$31 -> 0 | D31: Mini Sonho
A32: =$C$6*0.2 -> 0 | B32: =IFERROR(VLOOKUP(D32,PREÇOS!$B$2:$C$32,2,FALSE),0) -> 0.85 | C32: =$A$32*$B$32 -> 0 | D32: Mini cookies
D33: FOLHADOS
A34: =$C$6*0.7 -> 0 | B34: =IFERROR(VLOOKUP(D34,PREÇOS!$B$2:$C$32,2,FALSE),0) -> 1.6 | C34: =$A$34*$B$34 -> 0 | D34: Mini Croissant
A35: =$C$6*0.5 -> 0 | B35: =IFERROR(VLOOKUP(D35,PREÇOS!$B$2:$C$32,2,FALSE),0) -> 1.8 | C35: =$A$35*$B$35 -> 0 | D35: Mini Pão de Chocolate
A36: =$C$6*0.5 -> 0 | B36: =IFERROR(VLOOKUP(D36,PREÇOS!$B$2:$C$32,2,FALSE),0) -> 0.95 | C36: =$A$36*$B$36 -> 0 | D36: Mini Folhado Salgado
A38: Total: | C38: =SUM(C9:C37) -> 0
A40: Produtos Volantes
A41: PAX | C41: 0 | D41: PADARIA
A42: unidades | D42: Pães salgados e doces
A43: =$C$41*0.7 -> 0 | B43: =IFERROR(VLOOKUP(D43,PREÇOS!$B$2:$C$32,2,FALSE),0) -> 0.63 | C43: =$A$43*$B$43 -> 0 | D43: Pão de queijo
A44: =$C$41*0.3 -> 0 | B44: =IFERROR(VLOOKUP(D44,PREÇOS!$B$2:$C$32,2,FALSE),0) -> 0.95 | C44: =$A$44*$B$44 -> 0 | D44: Folhado Salgado
...

Sheet DIA 4
A1: HOTEL NANNAI MURO ALTO
A2: PADARIA / CONFEITARIA
A4: PRODUÇÃO | B4: Dia: 04/06/2026
A5: RESTAURANTE NANNAI
A6: PAX | C6: 0 | D6: PADARIA | F6: ATENÇÃO ALTERAR SOMENTE EM VERMELHO, ALTERAR SOMENTE O NUMERO DE PESSOAS PAX
A8: unidades | B8: VALOR | C8: TOTAL | D8: PÃES SALGADOS
A9: =$C$6*0.9 -> 0 | B9: =IFERROR(VLOOKUP(D9,PREÇOS!$B$2:$C$32,2,FALSE),0) -> 0.4 | C9: =$A$9*$B$9 -> 0 | D9: Mini Pão Francês
A10: =$C$6*0.2 -> 0 | B10: =IFERROR(VLOOKUP(D10,PREÇOS!$B$2:$C$32,2,FALSE),0) -> 0.6 | C10: =$A$10*$B$10 -> 0 | D10: Mini Pão Integral
A11: =$C$6*0.2 -> 0 | B11: =IFERROR(VLOOKUP(D11,PREÇOS!$B$2:$C$32,2,FALSE),0) -> 0.8 | C11: =$A$11*$B$11 -> 0 | D11: Mini Australiano
A12: =$C$6*0.2 -> 0 | B12: =IFERROR(VLOOKUP(D12,PREÇOS!$B$2:$C$32,2,FALSE),0) -> 0.45 | C12: =$A$12*$B$12 -> 0 | D12: Mini Pão Gergilim
A13: =$C$6*0.2 -> 0 | B13: =IFERROR(VLOOKUP(D13,PREÇOS!$B$2:$C$32,2,FALSE),0) -> 0 | C13: =$A$13*$B$13 -> 0 | D13: Mini Pão de Milho ou
A14: =$C$6*0.1 -> 0 | B14: =IFERROR(VLOOKUP(D14,PREÇOS!$B$2:$C$32,2,FALSE),0) -> 0 | C14: =$A$14*$B$14 -> 0 | D14: Mini Baguete Rustica
A15: =$C$6*0.2 -> 0 | B15: =IFERROR(VLOOKUP(D15,PREÇOS!$B$2:$C$32,2,FALSE),0) -> 0.8 | C15: =$A$15*$B$15 -> 0 | D15: Mini Pão Calabresa
A16: =$C$6*0.2 -> 0 | B16: =IFERROR(VLOOKUP(D16,PREÇOS!$B$2:$C$32,2,FALSE),0) -> 0.7 | C16: =$A$16*$B$16 -> 0 | D16: Mini Pão Delicia recheado
A17: =$C$6*0.01 -> 0 | B17: =IFERROR(VLOOKUP(D17,PREÇOS!$B$2:$C$32,2,FALSE),0) -> 1.55 | C17: =$A$17*$B$17 -> 0 | D17: Focaccia recheada
A18: =$C$6*0.3 -> 0 | B18: =IFERROR(VLOOKUP(D18,PREÇOS!$B$2:$C$32,2,FALSE),0) -> 0.4 | C18: =$A$18*$B$18 -> 0 | D18: Mini Tiger
A19: =$C$6*0.2 -> 0 | B19: =IFERROR(VLOOKUP(D19,PREÇOS!$B$2:$C$32,2,FALSE),0) -> 0.8 | C19: =$A$19*$B$19 -> 0 | D19: Mini Pão de Frios
A20: =$C$6*0.004 -> 0 | B20: =IFERROR(VLOOKUP(D20,PREÇOS!$B$2:$C$32,2,FALSE),0) -> 3 | C20: =$A$20*$B$20 -> 0 | D20: Pão de Forma integral
A21: =$C$6*0.009 -> 0 | B21: =IFERROR(VLOOKUP(D21,PREÇOS!$B$2:$C$32,2,FALSE),0) -> 2.8 | C21: =$A$21*$B$21 -> 0 | D21: Pão de forma Tradicional
A22: =$C$6*0.004 -> 0 | B22: =IFERROR(VLOOKUP(D22,PREÇOS!$B$2:$C$32,2,FALSE),0) -> 3 | C22: =$A$22*$B$22 -> 0 | D22: Pão de Forma Maritoso
A23: =$C$6*0.04 -> 0 | B23: =IFERROR(VLOOKUP(D23,PREÇOS!$B$2:$C$32,2,FALSE),0) -> 2.6 | C23: =$A$23*$B$23 -> 0 | D23: Baguete Francesa 300g
A24: =$C$6*0.04 -> 0 | B24: =IFERROR(VLOOKUP(D24,PREÇOS!$B$2:$C$32,2,FALSE),0) -> 3.8 | C24: =$A$24*$B$24 -> 0 | D24: Pães de Decoração Rustico
D25: PÃES DOCES
A26: =$C$6*0.2 -> 0 | B26: =IFERROR(VLOOKUP(D26,PREÇOS!$B$2:$C$32,2,FALSE),0) -> 0.6 | C26: =$A$26*$B$26 -> 0 | D26: Mini Brioche ou Pão de Açucar
A27: =$C$6*0.2 -> 0 | B27: =IFERROR(VLOOKUP(D27,PREÇOS!$B$2:$C$32,2,FALSE),0) -> 0.5 | C27: =$A$27*$B$27 -> 0 | D27: Mini Bisnaguinha
A28: =$C$6*0.1 -> 0 | B28: =IFERROR(VLOOKUP(D28,PREÇOS!$B$2:$C$32,2,FALSE),0) -> 0.75 | C28: =$A$28*$B$28 -> 0 | D28: Mini Pão de coco
A29: =$C$6*0.1 -> 0 | B29: =IFERROR(VLOOKUP(D29,PREÇOS!$B$2:$C$32,2,FALSE),0) -> 0.6 | C29: =$A$29*$B$29 -> 0 | D29: Mini Pão doce
A30: =$C$6*0.2 -> 0 | B30: =IFERROR(VLOOKUP(D30,PREÇOS!$B$2:$C$32,2,FALSE),0) -> 0.8 | C30: =$A$30*$B$30 -> 0 | D30: Mini Donuts
A31: =$C$6*0.2 -> 0 | B31: =IFERROR(VLOOKUP(D31,PREÇOS!$B$2:$C$32,2,FALSE),0) -> 0.8 | C31: =$A$31*$B$31 -> 0 | D31: Mini Sonho
A32: =$C$6*0.2 -> 0 | B32: =IFERROR(VLOOKUP(D32,PREÇOS!$B$2:$C$32,2,FALSE),0) -> 0.85 | C32: =$A$32*$B$32 -> 0 | D32: Mini cookies
D33: FOLHADOS
A34: =$C$6*0.7 -> 0 | B34: =IFERROR(VLOOKUP(D34,PREÇOS!$B$2:$C$32,2,FALSE),0) -> 1.6 | C34: =$A$34*$B$34 -> 0 | D34: Mini Croissant
A35: =$C$6*0.5 -> 0 | B35: =IFERROR(VLOOKUP(D35,PREÇOS!$B$2:$C$32,2,FALSE),0) -> 1.8 | C35: =$A$35*$B$35 -> 0 | D35: Mini Pão de Chocolate
A36: =$C$6*0.5 -> 0 | B36: =IFERROR(VLOOKUP(D36,PREÇOS!$B$2:$C$32,2,FALSE),0) -> 0.95 | C36: =$A$36*$B$36 -> 0 | D36: Mini Folhado Salgado
A38: Total: | C38: =SUM(C9:C37) -> 0
A40: Produtos Volantes
A41: PAX | C41: 0 | D41: PADARIA
A42: unidades | D42: Pães salgados e doces
A43: =$C$41*0.7 -> 0 | B43: =IFERROR(VLOOKUP(D43,PREÇOS!$B$2:$C$32,2,FALSE),0) -> 0.63 | C43: =$A$43*$B$43 -> 0 | D43: Pão de queijo
A44: =$C$41*0.3 -> 0 | B44: =IFERROR(VLOOKUP(D44,PREÇOS!$B$2:$C$32,2,FALSE),0) -> 0.95 | C44: =$A$44*$B$44 -> 0 | D44: Folhado Salgado
...

Sheet DIA 5
A1: HOTEL NANNAI MURO ALTO
A2: PADARIA / CONFEITARIA
A4: PRODUÇÃO | B4: Dia: 05/06/2026
A5: RESTAURANTE NANNAI
A6: PAX | C6: 0 | D6: PADARIA | F6: ATENÇÃO ALTERAR SOMENTE EM VERMELHO, ALTERAR SOMENTE O NUMERO DE PESSOAS PAX
A8: unidades | B8: VALOR | C8: TOTAL | D8: PÃES SALGADOS
A9: =$C$6*0.9 -> 0 | B9: =IFERROR(VLOOKUP(D9,PREÇOS!$B$2:$C$32,2,FALSE),0) -> 0.4 | C9: =$A$9*$B$9 -> 0 | D9: Mini Pão Francês
A10: =$C$6*0.2 -> 0 | B10: =IFERROR(VLOOKUP(D10,PREÇOS!$B$2:$C$32,2,FALSE),0) -> 0.6 | C10: =$A$10*$B$10 -> 0 | D10: Mini Pão Integral
A11: =$C$6*0.2 -> 0 | B11: =IFERROR(VLOOKUP(D11,PREÇOS!$B$2:$C$32,2,FALSE),0) -> 0.8 | C11: =$A$11*$B$11 -> 0 | D11: Mini Australiano
A12: =$C$6*0.2 -> 0 | B12: =IFERROR(VLOOKUP(D12,PREÇOS!$B$2:$C$32,2,FALSE),0) -> 0.45 | C12: =$A$12*$B$12 -> 0 | D12: Mini Pão Gergilim
A13: =$C$6*0.2 -> 0 | B13: =IFERROR(VLOOKUP(D13,PREÇOS!$B$2:$C$32,2,FALSE),0) -> 0 | C13: =$A$13*$B$13 -> 0 | D13: Mini Pão de Milho ou
A14: =$C$6*0.1 -> 0 | B14: =IFERROR(VLOOKUP(D14,PREÇOS!$B$2:$C$32,2,FALSE),0) -> 0 | C14: =$A$14*$B$14 -> 0 | D14: Mini Baguete Rustica
A15: =$C$6*0.2 -> 0 | B15: =IFERROR(VLOOKUP(D15,PREÇOS!$B$2:$C$32,2,FALSE),0) -> 0.8 | C15: =$A$15*$B$15 -> 0 | D15: Mini Pão Calabresa
A16: =$C$6*0.2 -> 0 | B16: =IFERROR(VLOOKUP(D16,PREÇOS!$B$2:$C$32,2,FALSE),0) -> 0.7 | C16: =$A$16*$B$16 -> 0 | D16: Mini Pão Delicia recheado
A17: =$C$6*0.01 -> 0 | B17: =IFERROR(VLOOKUP(D17,PREÇOS!$B$2:$C$32,2,FALSE),0) -> 1.55 | C17: =$A$17*$B$17 -> 0 | D17: Focaccia recheada
A18: =$C$6*0.3 -> 0 | B18: =IFERROR(VLOOKUP(D18,PREÇOS!$B$2:$C$32,2,FALSE),0) -> 0.4 | C18: =$A$18*$B$18 -> 0 | D18: Mini Tiger
A19: =$C$6*0.2 -> 0 | B19: =IFERROR(VLOOKUP(D19,PREÇOS!$B$2:$C$32,2,FALSE),0) -> 0.8 | C19: =$A$19*$B$19 -> 0 | D19: Mini Pão de Frios
A20: =$C$6*0.004 -> 0 | B20: =IFERROR(VLOOKUP(D20,PREÇOS!$B$2:$C$32,2,FALSE),0) -> 3 | C20: =$A$20*$B$20 -> 0 | D20: Pão de Forma integral
A21: =$C$6*0.009 -> 0 | B21: =IFERROR(VLOOKUP(D21,PREÇOS!$B$2:$C$32,2,FALSE),0) -> 2.8 | C21: =$A$21*$B$21 -> 0 | D21: Pão de forma Tradicional
A22: =$C$6*0.004 -> 0 | B22: =IFERROR(VLOOKUP(D22,PREÇOS!$B$2:$C$32,2,FALSE),0) -> 3 | C22: =$A$22*$B$22 -> 0 | D22: Pão de Forma Maritoso
A23: =$C$6*0.04 -> 0 | B23: =IFERROR(VLOOKUP(D23,PREÇOS!$B$2:$C$32,2,FALSE),0) -> 2.6 | C23: =$A$23*$B$23 -> 0 | D23: Baguete Francesa 300g
A24: =$C$6*0.04 -> 0 | B24: =IFERROR(VLOOKUP(D24,PREÇOS!$B$2:$C$32,2,FALSE),0) -> 3.8 | C24: =$A$24*$B$24 -> 0 | D24: Pães de Decoração Rustico
D25: PÃES DOCES
A26: =$C$6*0.2 -> 0 | B26: =IFERROR(VLOOKUP(D26,PREÇOS!$B$2:$C$32,2,FALSE),0) -> 0.6 | C26: =$A$26*$B$26 -> 0 | D26: Mini Brioche ou Pão de Açucar
A27: =$C$6*0.2 -> 0 | B27: =IFERROR(VLOOKUP(D27,PREÇOS!$B$2:$C$32,2,FALSE),0) -> 0.5 | C27: =$A$27*$B$27 -> 0 | D27: Mini Bisnaguinha
A28: =$C$6*0.1 -> 0 | B28: =IFERROR(VLOOKUP(D28,PREÇOS!$B$2:$C$32,2,FALSE),0) -> 0.75 | C28: =$A$28*$B$28 -> 0 | D28: Mini Pão de coco
A29: =$C$6*0.1 -> 0 | B29: =IFERROR(VLOOKUP(D29,PREÇOS!$B$2:$C$32,2,FALSE),0) -> 0.6 | C29: =$A$29*$B$29 -> 0 | D29: Mini Pão doce
A30: =$C$6*0.2 -> 0 | B30: =IFERROR(VLOOKUP(D30,PREÇOS!$B$2:$C$32,2,FALSE),0) -> 0.8 | C30: =$A$30*$B$30 -> 0 | D30: Mini Donuts
A31: =$C$6*0.2 -> 0 | B31: =IFERROR(VLOOKUP(D31,PREÇOS!$B$2:$C$32,2,FALSE),0) -> 0.8 | C31: =$A$31*$B$31 -> 0 | D31: Mini Sonho
A32: =$C$6*0.2 -> 0 | B32: =IFERROR(VLOOKUP(D32,PREÇOS!$B$2:$C$32,2,FALSE),0) -> 0.85 | C32: =$A$32*$B$32 -> 0 | D32: Mini cookies
D33: FOLHADOS
A34: =$C$6*0.7 -> 0 | B34: =IFERROR(VLOOKUP(D34,PREÇOS!$B$2:$C$32,2,FALSE),0) -> 1.6 | C34: =$A$34*$B$34 -> 0 | D34: Mini Croissant
A35: =$C$6*0.5 -> 0 | B35: =IFERROR(VLOOKUP(D35,PREÇOS!$B$2:$C$32,2,FALSE),0) -> 1.8 | C35: =$A$35*$B$35 -> 0 | D35: Mini Pão de Chocolate
A36: =$C$6*0.5 -> 0 | B36: =IFERROR(VLOOKUP(D36,PREÇOS!$B$2:$C$32,2,FALSE),0) -> 0.95 | C36: =$A$36*$B$36 -> 0 | D36: Mini Folhado Salgado
A38: Total: | C38: =SUM(C9:C37) -> 0
A40: Produtos Volantes
A41: PAX | C41: 0 | D41: PADARIA
A42: unidades | D42: Pães salgados e doces
A43: =$C$41*0.7 -> 0 | B43: =IFERROR(VLOOKUP(D43,PREÇOS!$B$2:$C$32,2,FALSE),0) -> 0.63 | C43: =$A$43*$B$43 -> 0 | D43: Pão de queijo
A44: =$C$41*0.3 -> 0 | B44: =IFERROR(VLOOKUP(D44,PREÇOS!$B$2:$C$32,2,FALSE),0) -> 0.95 | C44: =$A$44*$B$44 -> 0 | D44: Folhado Salgado
...

Sheet DIA 6
A1: HOTEL NANNAI MURO ALTO
A2: PADARIA / CONFEITARIA
A4: PRODUÇÃO | B4: Dia: 06/06/2026
A5: RESTAURANTE NANNAI
A6: PAX | C6: 200 | D6: PADARIA | F6: ATENÇÃO ALTERAR SOMENTE EM VERMELHO, ALTERAR SOMENTE O NUMERO DE PESSOAS PAX
A8: unidades | B8: VALOR | C8: TOTAL | D8: PÃES SALGADOS
A9: =$C$6*0.9 -> 180 | B9: =IFERROR(VLOOKUP(D9,PREÇOS!$B$2:$C$32,2,FALSE),0) -> 0.4 | C9: =$A$9*$B$9 -> 72 | D9: Mini Pão Francês
A10: =$C$6*0.2 -> 40 | B10: =IFERROR(VLOOKUP(D10,PREÇOS!$B$2:$C$32,2,FALSE),0) -> 0.6 | C10: =$A$10*$B$10 -> 24 | D10: Mini Pão Integral
A11: =$C$6*0.2 -> 40 | B11: =IFERROR(VLOOKUP(D11,PREÇOS!$B$2:$C$32,2,FALSE),0) -> 0.8 | C11: =$A$11*$B$11 -> 32 | D11: Mini Australiano
A12: =$C$6*0.2 -> 40 | B12: =IFERROR(VLOOKUP(D12,PREÇOS!$B$2:$C$32,2,FALSE),0) -> 0.45 | C12: =$A$12*$B$12 -> 18 | D12: Mini Pão Gergilim
A13: =$C$6*0.2 -> 40 | B13: =IFERROR(VLOOKUP(D13,PREÇOS!$B$2:$C$32,2,FALSE),0) -> 0 | C13: =$A$13*$B$13 -> 0 | D13: Mini Pão de Milho ou
A14: =$C$6*0.1 -> 20 | B14: =IFERROR(VLOOKUP(D14,PREÇOS!$B$2:$C$32,2,FALSE),0) -> 0 | C14: =$A$14*$B$14 -> 0 | D14: Mini Baguete Rustica
A15: =$C$6*0.2 -> 40 | B15: =IFERROR(VLOOKUP(D15,PREÇOS!$B$2:$C$32,2,FALSE),0) -> 0.8 | C15: =$A$15*$B$15 -> 32 | D15: Mini Pão Calabresa
A16: =$C$6*0.2 -> 40 | B16: =IFERROR(VLOOKUP(D16,PREÇOS!$B$2:$C$32,2,FALSE),0) -> 0.7 | C16: =$A$16*$B$16 -> 28 | D16: Mini Pão Delicia recheado
A17: =$C$6*0.01 -> 2 | B17: =IFERROR(VLOOKUP(D17,PREÇOS!$B$2:$C$32,2,FALSE),0) -> 1.55 | C17: =$A$17*$B$17 -> 3.1 | D17: Focaccia recheada
A18: =$C$6*0.3 -> 60 | B18: =IFERROR(VLOOKUP(D18,PREÇOS!$B$2:$C$32,2,FALSE),0) -> 0.4 | C18: =$A$18*$B$18 -> 24 | D18: Mini Tiger
A19: =$C$6*0.2 -> 40 | B19: =IFERROR(VLOOKUP(D19,PREÇOS!$B$2:$C$32,2,FALSE),0) -> 0.8 | C19: =$A$19*$B$19 -> 32 | D19: Mini Pão de Frios
A20: =$C$6*0.004 -> 0.8 | B20: =IFERROR(VLOOKUP(D20,PREÇOS!$B$2:$C$32,2,FALSE),0) -> 3 | C20: =$A$20*$B$20 -> 2.4 | D20: Pão de Forma integral
A21: =$C$6*0.009 -> 1.8 | B21: =IFERROR(VLOOKUP(D21,PREÇOS!$B$2:$C$32,2,FALSE),0) -> 2.8 | C21: =$A$21*$B$21 -> 5.04 | D21: Pão de forma Tradicional
A22: =$C$6*0.004 -> 0.8 | B22: =IFERROR(VLOOKUP(D22,PREÇOS!$B$2:$C$32,2,FALSE),0) -> 3 | C22: =$A$22*$B$22 -> 2.4 | D22: Pão de Forma Maritoso
A23: =$C$6*0.04 -> 8 | B23: =IFERROR(VLOOKUP(D23,PREÇOS!$B$2:$C$32,2,FALSE),0) -> 2.6 | C23: =$A$23*$B$23 -> 20.8 | D23: Baguete Francesa 300g
A24: =$C$6*0.04 -> 8 | B24: =IFERROR(VLOOKUP(D24,PREÇOS!$B$2:$C$32,2,FALSE),0) -> 3.8 | C24: =$A$24*$B$24 -> 30.4 | D24: Pães de Decoração Rustico
D25: PÃES DOCES
A26: =$C$6*0.2 -> 40 | B26: =IFERROR(VLOOKUP(D26,PREÇOS!$B$2:$C$32,2,FALSE),0) -> 0.6 | C26: =$A$26*$B$26 -> 24 | D26: Mini Brioche ou Pão de Açucar
A27: =$C$6*0.2 -> 40 | B27: =IFERROR(VLOOKUP(D27,PREÇOS!$B$2:$C$32,2,FALSE),0) -> 0.5 | C27: =$A$27*$B$27 -> 20 | D27: Mini Bisnaguinha
A28: =$C$6*0.1 -> 20 | B28: =IFERROR(VLOOKUP(D28,PREÇOS!$B$2:$C$32,2,FALSE),0) -> 0.75 | C28: =$A$28*$B$28 -> 15 | D28: Mini Pão de coco
A29: =$C$6*0.1 -> 20 | B29: =IFERROR(VLOOKUP(D29,PREÇOS!$B$2:$C$32,2,FALSE),0) -> 0.6 | C29: =$A$29*$B$29 -> 12 | D29: Mini Pão doce
A30: =$C$6*0.2 -> 40 | B30: =IFERROR(VLOOKUP(D30,PREÇOS!$B$2:$C$32,2,FALSE),0) -> 0.8 | C30: =$A$30*$B$30 -> 32 | D30: Mini Donuts
A31: =$C$6*0.2 -> 40 | B31: =IFERROR(VLOOKUP(D31,PREÇOS!$B$2:$C$32,2,FALSE),0) -> 0.8 | C31: =$A$31*$B$31 -> 32 | D31: Mini Sonho
A32: =$C$6*0.2 -> 40 | B32: =IFERROR(VLOOKUP(D32,PREÇOS!$B$2:$C$32,2,FALSE),0) -> 0.85 | C32: =$A$32*$B$32 -> 34 | D32: Mini cookies
D33: FOLHADOS
A34: =$C$6*0.7 -> 140 | B34: =IFERROR(VLOOKUP(D34,PREÇOS!$B$2:$C$32,2,FALSE),0) -> 1.6 | C34: =$A$34*$B$34 -> 224 | D34: Mini Croissant
A35: =$C$6*0.5 -> 100 | B35: =IFERROR(VLOOKUP(D35,PREÇOS!$B$2:$C$32,2,FALSE),0) -> 1.8 | C35: =$A$35*$B$35 -> 180 | D35: Mini Pão de Chocolate
A36: =$C$6*0.5 -> 100 | B36: =IFERROR(VLOOKUP(D36,PREÇOS!$B$2:$C$32,2,FALSE),0) -> 0.95 | C36: =$A$36*$B$36 -> 95 | D36: Mini Folhado Salgado
A38: Total: | C38: =SUM(C9:C37) -> 994.14
A40: Produtos Volantes
A41: PAX | C41: 200 | D41: PADARIA
A42: unidades | D42: Pães salgados e doces
A43: =$C$41*0.7 -> 140 | B43: =IFERROR(VLOOKUP(D43,PREÇOS!$B$2:$C$32,2,FALSE),0) -> 0.63 | C43: =$A$43*$B$43 -> 88.2 | D43: Pão de queijo
A44: =$C$41*0.3 -> 60 | B44: =IFERROR(VLOOKUP(D44,PREÇOS!$B$2:$C$32,2,FALSE),0) -> 0.95 | C44: =$A$44*$B$44 -> 57 | D44: Folhado Salgado
...

Sheet DIA 7
A1: HOTEL NANNAI MURO ALTO
A2: PADARIA / CONFEITARIA
A4: PRODUÇÃO | B4: Dia: 07/06/2026
A5: RESTAURANTE NANNAI
A6: PAX | C6: 0 | D6: PADARIA | F6: ATENÇÃO ALTERAR SOMENTE EM VERMELHO, ALTERAR SOMENTE O NUMERO DE PESSOAS PAX
A8: unidades | B8: VALOR | C8: TOTAL | D8: PÃES SALGADOS
A9: =$C$6*0.9 -> 0 | B9: =IFERROR(VLOOKUP(D9,PREÇOS!$B$2:$C$32,2,FALSE),0) -> 0.4 | C9: =$A$9*$B$9 -> 0 | D9: Mini Pão Francês
A10: =$C$6*0.2 -> 0 | B10: =IFERROR(VLOOKUP(D10,PREÇOS!$B$2:$C$32,2,FALSE),0) -> 0.6 | C10: =$A$10*$B$10 -> 0 | D10: Mini Pão Integral
A11: =$C$6*0.2 -> 0 | B11: =IFERROR(VLOOKUP(D11,PREÇOS!$B$2:$C$32,2,FALSE),0) -> 0.8 | C11: =$A$11*$B$11 -> 0 | D11: Mini Australiano
A12: =$C$6*0.2 -> 0 | B12: =IFERROR(VLOOKUP(D12,PREÇOS!$B$2:$C$32,2,FALSE),0) -> 0.45 | C12: =$A$12*$B$12 -> 0 | D12: Mini Pão Gergilim
A13: =$C$6*0.2 -> 0 | B13: =IFERROR(VLOOKUP(D13,PREÇOS!$B$2:$C$32,2,FALSE),0) -> 0 | C13: =$A$13*$B$13 -> 0 | D13: Mini Pão de Milho ou
A14: =$C$6*0.1 -> 0 | B14: =IFERROR(VLOOKUP(D14,PREÇOS!$B$2:$C$32,2,FALSE),0) -> 0 | C14: =$A$14*$B$14 -> 0 | D14: Mini Baguete Rustica
A15: =$C$6*0.2 -> 0 | B15: =IFERROR(VLOOKUP(D15,PREÇOS!$B$2:$C$32,2,FALSE),0) -> 0.8 | C15: =$A$15*$B$15 -> 0 | D15: Mini Pão Calabresa
A16: =$C$6*0.2 -> 0 | B16: =IFERROR(VLOOKUP(D16,PREÇOS!$B$2:$C$32,2,FALSE),0) -> 0.7 | C16: =$A$16*$B$16 -> 0 | D16: Mini Pão Delicia recheado
A17: =$C$6*0.01 -> 0 | B17: =IFERROR(VLOOKUP(D17,PREÇOS!$B$2:$C$32,2,FALSE),0) -> 1.55 | C17: =$A$17*$B$17 -> 0 | D17: Focaccia recheada
A18: =$C$6*0.3 -> 0 | B18: =IFERROR(VLOOKUP(D18,PREÇOS!$B$2:$C$32,2,FALSE),0) -> 0.4 | C18: =$A$18*$B$18 -> 0 | D18: Mini Tiger
A19: =$C$6*0.2 -> 0 | B19: =IFERROR(VLOOKUP(D19,PREÇOS!$B$2:$C$32,2,FALSE),0) -> 0.8 | C19: =$A$19*$B$19 -> 0 | D19: Mini Pão de Frios
A20: =$C$6*0.004 -> 0 | B20: =IFERROR(VLOOKUP(D20,PREÇOS!$B$2:$C$32,2,FALSE),0) -> 3 | C20: =$A$20*$B$20 -> 0 | D20: Pão de Forma integral
A21: =$C$6*0.009 -> 0 | B21: =IFERROR(VLOOKUP(D21,PREÇOS!$B$2:$C$32,2,FALSE),0) -> 2.8 | C21: =$A$21*$B$21 -> 0 | D21: Pão de forma Tradicional
A22: =$C$6*0.004 -> 0 | B22: =IFERROR(VLOOKUP(D22,PREÇOS!$B$2:$C$32,2,FALSE),0) -> 3 | C22: =$A$22*$B$22 -> 0 | D22: Pão de Forma Maritoso
A23: =$C$6*0.04 -> 0 | B23: =IFERROR(VLOOKUP(D23,PREÇOS!$B$2:$C$32,2,FALSE),0) -> 2.6 | C23: =$A$23*$B$23 -> 0 | D23: Baguete Francesa 300g
A24: =$C$6*0.04 -> 0 | B24: =IFERROR(VLOOKUP(D24,PREÇOS!$B$2:$C$32,2,FALSE),0) -> 3.8 | C24: =$A$24*$B$24 -> 0 | D24: Pães de Decoração Rustico
D25: PÃES DOCES
A26: =$C$6*0.2 -> 0 | B26: =IFERROR(VLOOKUP(D26,PREÇOS!$B$2:$C$32,2,FALSE),0) -> 0.6 | C26: =$A$26*$B$26 -> 0 | D26: Mini Brioche ou Pão de Açucar
A27: =$C$6*0.2 -> 0 | B27: =IFERROR(VLOOKUP(D27,PREÇOS!$B$2:$C$32,2,FALSE),0) -> 0.5 | C27: =$A$27*$B$27 -> 0 | D27: Mini Bisnaguinha
A28: =$C$6*0.1 -> 0 | B28: =IFERROR(VLOOKUP(D28,PREÇOS!$B$2:$C$32,2,FALSE),0) -> 0.75 | C28: =$A$28*$B$28 -> 0 | D28: Mini Pão de coco
A29: =$C$6*0.1 -> 0 | B29: =IFERROR(VLOOKUP(D29,PREÇOS!$B$2:$C$32,2,FALSE),0) -> 0.6 | C29: =$A$29*$B$29 -> 0 | D29: Mini Pão doce
A30: =$C$6*0.2 -> 0 | B30: =IFERROR(VLOOKUP(D30,PREÇOS!$B$2:$C$32,2,FALSE),0) -> 0.8 | C30: =$A$30*$B$30 -> 0 | D30: Mini Donuts
A31: =$C$6*0.2 -> 0 | B31: =IFERROR(VLOOKUP(D31,PREÇOS!$B$2:$C$32,2,FALSE),0) -> 0.8 | C31: =$A$31*$B$31 -> 0 | D31: Mini Sonho
A32: =$C$6*0.2 -> 0 | B32: =IFERROR(VLOOKUP(D32,PREÇOS!$B$2:$C$32,2,FALSE),0) -> 0.85 | C32: =$A$32*$B$32 -> 0 | D32: Mini cookies
D33: FOLHADOS
A34: =$C$6*0.7 -> 0 | B34: =IFERROR(VLOOKUP(D34,PREÇOS!$B$2:$C$32,2,FALSE),0) -> 1.6 | C34: =$A$34*$B$34 -> 0 | D34: Mini Croissant
A35: =$C$6*0.5 -> 0 | B35: =IFERROR(VLOOKUP(D35,PREÇOS!$B$2:$C$32,2,FALSE),0) -> 1.8 | C35: =$A$35*$B$35 -> 0 | D35: Mini Pão de Chocolate
A36: =$C$6*0.5 -> 0 | B36: =IFERROR(VLOOKUP(D36,PREÇOS!$B$2:$C$32,2,FALSE),0) -> 0.95 | C36: =$A$36*$B$36 -> 0 | D36: Mini Folhado Salgado
A38: Total: | C38: =SUM(C9:C37) -> 0
A40: Produtos Volantes
A41: PAX | C41: 0 | D41: PADARIA
A42: unidades | D42: Pães salgados e doces
A43: =$C$41*0.7 -> 0 | B43: =IFERROR(VLOOKUP(D43,PREÇOS!$B$2:$C$32,2,FALSE),0) -> 0.63 | C43: =$A$43*$B$43 -> 0 | D43: Pão de queijo
A44: =$C$41*0.3 -> 0 | B44: =IFERROR(VLOOKUP(D44,PREÇOS!$B$2:$C$32,2,FALSE),0) -> 0.95 | C44: =$A$44*$B$44 -> 0 | D44: Folhado Salgado
...

Sheet DIA 8
A1: HOTEL NANNAI MURO ALTO
A2: PADARIA / CONFEITARIA
A4: PRODUÇÃO | B4: Dia: 08/06/2026
A5: RESTAURANTE NANNAI
A6: PAX | C6: 0 | D6: PADARIA | F6: ATENÇÃO ALTERAR SOMENTE EM VERMELHO, ALTERAR SOMENTE O NUMERO DE PESSOAS PAX
A8: unidades | B8: VALOR | C8: TOTAL | D8: PÃES SALGADOS
A9: =$C$6*0.9 -> 0 | B9: =IFERROR(VLOOKUP(D9,PREÇOS!$B$2:$C$32,2,FALSE),0) -> 0.4 | C9: =$A$9*$B$9 -> 0 | D9: Mini Pão Francês
A10: =$C$6*0.2 -> 0 | B10: =IFERROR(VLOOKUP(D10,PREÇOS!$B$2:$C$32,2,FALSE),0) -> 0.6 | C10: =$A$10*$B$10 -> 0 | D10: Mini Pão Integral
A11: =$C$6*0.2 -> 0 | B11: =IFERROR(VLOOKUP(D11,PREÇOS!$B$2:$C$32,2,FALSE),0) -> 0.8 | C11: =$A$11*$B$11 -> 0 | D11: Mini Australiano
A12: =$C$6*0.2 -> 0 | B12: =IFERROR(VLOOKUP(D12,PREÇOS!$B$2:$C$32,2,FALSE),0) -> 0.45 | C12: =$A$12*$B$12 -> 0 | D12: Mini Pão Gergilim
A13: =$C$6*0.2 -> 0 | B13: =IFERROR(VLOOKUP(D13,PREÇOS!$B$2:$C$32,2,FALSE),0) -> 0 | C13: =$A$13*$B$13 -> 0 | D13: Mini Pão de Milho ou
A14: =$C$6*0.1 -> 0 | B14: =IFERROR(VLOOKUP(D14,PREÇOS!$B$2:$C$32,2,FALSE),0) -> 0 | C14: =$A$14*$B$14 -> 0 | D14: Mini Baguete Rustica
A15: =$C$6*0.2 -> 0 | B15: =IFERROR(VLOOKUP(D15,PREÇOS!$B$2:$C$32,2,FALSE),0) -> 0.8 | C15: =$A$15*$B$15 -> 0 | D15: Mini Pão Calabresa
A16: =$C$6*0.2 -> 0 | B16: =IFERROR(VLOOKUP(D16,PREÇOS!$B$2:$C$32,2,FALSE),0) -> 0.7 | C16: =$A$16*$B$16 -> 0 | D16: Mini Pão Delicia recheado
A17: =$C$6*0.01 -> 0 | B17: =IFERROR(VLOOKUP(D17,PREÇOS!$B$2:$C$32,2,FALSE),0) -> 1.55 | C17: =$A$17*$B$17 -> 0 | D17: Focaccia recheada
A18: =$C$6*0.3 -> 0 | B18: =IFERROR(VLOOKUP(D18,PREÇOS!$B$2:$C$32,2,FALSE),0) -> 0.4 | C18: =$A$18*$B$18 -> 0 | D18: Mini Tiger
A19: =$C$6*0.2 -> 0 | B19: =IFERROR(VLOOKUP(D19,PREÇOS!$B$2:$C$32,2,FALSE),0) -> 0.8 | C19: =$A$19*$B$19 -> 0 | D19: Mini Pão de Frios
A20: =$C$6*0.004 -> 0 | B20: =IFERROR(VLOOKUP(D20,PREÇOS!$B$2:$C$32,2,FALSE),0) -> 3 | C20: =$A$20*$B$20 -> 0 | D20: Pão de Forma integral
A21: =$C$6*0.009 -> 0 | B21: =IFERROR(VLOOKUP(D21,PREÇOS!$B$2:$C$32,2,FALSE),0) -> 2.8 | C21: =$A$21*$B$21 -> 0 | D21: Pão de forma Tradicional
A22: =$C$6*0.004 -> 0 | B22: =IFERROR(VLOOKUP(D22,PREÇOS!$B$2:$C$32,2,FALSE),0) -> 3 | C22: =$A$22*$B$22 -> 0 | D22: Pão de Forma Maritoso
A23: =$C$6*0.04 -> 0 | B23: =IFERROR(VLOOKUP(D23,PREÇOS!$B$2:$C$32,2,FALSE),0) -> 2.6 | C23: =$A$23*$B$23 -> 0 | D23: Baguete Francesa 300g
A24: =$C$6*0.04 -> 0 | B24: =IFERROR(VLOOKUP(D24,PREÇOS!$B$2:$C$32,2,FALSE),0) -> 3.8 | C24: =$A$24*$B$24 -> 0 | D24: Pães de Decoração Rustico
D25: PÃES DOCES
A26: =$C$6*0.2 -> 0 | B26: =IFERROR(VLOOKUP(D26,PREÇOS!$B$2:$C$32,2,FALSE),0) -> 0.6 | C26: =$A$26*$B$26 -> 0 | D26: Mini Brioche ou Pão de Açucar
A27: =$C$6*0.2 -> 0 | B27: =IFERROR(VLOOKUP(D27,PREÇOS!$B$2:$C$32,2,FALSE),0) -> 0.5 | C27: =$A$27*$B$27 -> 0 | D27: Mini Bisnaguinha
A28: =$C$6*0.1 -> 0 | B28: =IFERROR(VLOOKUP(D28,PREÇOS!$B$2:$C$32,2,FALSE),0) -> 0.75 | C28: =$A$28*$B$28 -> 0 | D28: Mini Pão de coco
A29: =$C$6*0.1 -> 0 | B29: =IFERROR(VLOOKUP(D29,PREÇOS!$B$2:$C$32,2,FALSE),0) -> 0.6 | C29: =$A$29*$B$29 -> 0 | D29: Mini Pão doce
A30: =$C$6*0.2 -> 0 | B30: =IFERROR(VLOOKUP(D30,PREÇOS!$B$2:$C$32,2,FALSE),0) -> 0.8 | C30: =$A$30*$B$30 -> 0 | D30: Mini Donuts
A31: =$C$6*0.2 -> 0 | B31: =IFERROR(VLOOKUP(D31,PREÇOS!$B$2:$C$32,2,FALSE),0) -> 0.8 | C31: =$A$31*$B$31 -> 0 | D31: Mini Sonho
A32: =$C$6*0.2 -> 0 | B32: =IFERROR(VLOOKUP(D32,PREÇOS!$B$2:$C$32,2,FALSE),0) -> 0.85 | C32: =$A$32*$B$32 -> 0 | D32: Mini cookies
D33: FOLHADOS
A34: =$C$6*0.7 -> 0 | B34: =IFERROR(VLOOKUP(D34,PREÇOS!$B$2:$C$32,2,FALSE),0) -> 1.6 | C34: =$A$34*$B$34 -> 0 | D34: Mini Croissant
A35: =$C$6*0.5 -> 0 | B35: =IFERROR(VLOOKUP(D35,PREÇOS!$B$2:$C$32,2,FALSE),0) -> 1.8 | C35: =$A$35*$B$35 -> 0 | D35: Mini Pão de Chocolate
A36: =$C$6*0.5 -> 0 | B36: =IFERROR(VLOOKUP(D36,PREÇOS!$B$2:$C$32,2,FALSE),0) -> 0.95 | C36: =$A$36*$B$36 -> 0 | D36: Mini Folhado Salgado
A38: Total: | C38: =SUM(C9:C37) -> 0
A40: Produtos Volantes
A41: PAX | C41: 0 | D41: PADARIA
A42: unidades | D42: Pães salgados e doces
A43: =$C$41*0.7 -> 0 | B43: =IFERROR(VLOOKUP(D43,PREÇOS!$B$2:$C$32,2,FALSE),0) -> 0.63 | C43: =$A$43*$B$43 -> 0 | D43: Pão de queijo
A44: =$C$41*0.3 -> 0 | B44: =IFERROR(VLOOKUP(D44,PREÇOS!$B$2:$C$32,2,FALSE),0) -> 0.95 | C44: =$A$44*$B$44 -> 0 | D44: Folhado Salgado
...

Sheet DIA 9
A1: HOTEL NANNAI MURO ALTO
A2: PADARIA / CONFEITARIA
A4: PRODUÇÃO | B4: Dia: 09/06/2026
A5: RESTAURANTE NANNAI
A6: PAX | C6: 0 | D6: PADARIA | F6: ATENÇÃO ALTERAR SOMENTE EM VERMELHO, ALTERAR SOMENTE O NUMERO DE PESSOAS PAX
A8: unidades | B8: VALOR | C8: TOTAL | D8: PÃES SALGADOS
A9: =$C$6*0.9 -> 0 | B9: =IFERROR(VLOOKUP(D9,PREÇOS!$B$2:$C$32,2,FALSE),0) -> 0.4 | C9: =$A$9*$B$9 -> 0 | D9: Mini Pão Francês
A10: =$C$6*0.2 -> 0 | B10: =IFERROR(VLOOKUP(D10,PREÇOS!$B$2:$C$32,2,FALSE),0) -> 0.6 | C10: =$A$10*$B$10 -> 0 | D10: Mini Pão Integral
A11: =$C$6*0.2 -> 0 | B11: =IFERROR(VLOOKUP(D11,PREÇOS!$B$2:$C$32,2,FALSE),0) -> 0.8 | C11: =$A$11*$B$11 -> 0 | D11: Mini Australiano
A12: =$C$6*0.2 -> 0 | B12: =IFERROR(VLOOKUP(D12,PREÇOS!$B$2:$C$32,2,FALSE),0) -> 0.45 | C12: =$A$12*$B$12 -> 0 | D12: Mini Pão Gergilim
A13: =$C$6*0.2 -> 0 | B13: =IFERROR(VLOOKUP(D13,PREÇOS!$B$2:$C$32,2,FALSE),0) -> 0 | C13: =$A$13*$B$13 -> 0 | D13: Mini Pão de Milho ou
A14: =$C$6*0.1 -> 0 | B14: =IFERROR(VLOOKUP(D14,PREÇOS!$B$2:$C$32,2,FALSE),0) -> 0 | C14: =$A$14*$B$14 -> 0 | D14: Mini Baguete Rustica
A15: =$C$6*0.2 -> 0 | B15: =IFERROR(VLOOKUP(D15,PREÇOS!$B$2:$C$32,2,FALSE),0) -> 0.8 | C15: =$A$15*$B$15 -> 0 | D15: Mini Pão Calabresa
A16: =$C$6*0.2 -> 0 | B16: =IFERROR(VLOOKUP(D16,PREÇOS!$B$2:$C$32,2,FALSE),0) -> 0.7 | C16: =$A$16*$B$16 -> 0 | D16: Mini Pão Delicia recheado
A17: =$C$6*0.01 -> 0 | B17: =IFERROR(VLOOKUP(D17,PREÇOS!$B$2:$C$32,2,FALSE),0) -> 1.55 | C17: =$A$17*$B$17 -> 0 | D17: Focaccia recheada
A18: =$C$6*0.3 -> 0 | B18: =IFERROR(VLOOKUP(D18,PREÇOS!$B$2:$C$32,2,FALSE),0) -> 0.4 | C18: =$A$18*$B$18 -> 0 | D18: Mini Tiger
A19: =$C$6*0.2 -> 0 | B19: =IFERROR(VLOOKUP(D19,PREÇOS!$B$2:$C$32,2,FALSE),0) -> 0.8 | C19: =$A$19*$B$19 -> 0 | D19: Mini Pão de Frios
A20: =$C$6*0.004 -> 0 | B20: =IFERROR(VLOOKUP(D20,PREÇOS!$B$2:$C$32,2,FALSE),0) -> 3 | C20: =$A$20*$B$20 -> 0 | D20: Pão de Forma integral
A21: =$C$6*0.009 -> 0 | B21: =IFERROR(VLOOKUP(D21,PREÇOS!$B$2:$C$32,2,FALSE),0) -> 2.8 | C21: =$A$21*$B$21 -> 0 | D21: Pão de forma Tradicional
A22: =$C$6*0.004 -> 0 | B22: =IFERROR(VLOOKUP(D22,PREÇOS!$B$2:$C$32,2,FALSE),0) -> 3 | C22: =$A$22*$B$22 -> 0 | D22: Pão de Forma Maritoso
A23: =$C$6*0.04 -> 0 | B23: =IFERROR(VLOOKUP(D23,PREÇOS!$B$2:$C$32,2,FALSE),0) -> 2.6 | C23: =$A$23*$B$23 -> 0 | D23: Baguete Francesa 300g
A24: =$C$6*0.04 -> 0 | B24: =IFERROR(VLOOKUP(D24,PREÇOS!$B$2:$C$32,2,FALSE),0) -> 3.8 | C24: =$A$24*$B$24 -> 0 | D24: Pães de Decoração Rustico
D25: PÃES DOCES
A26: =$C$6*0.2 -> 0 | B26: =IFERROR(VLOOKUP(D26,PREÇOS!$B$2:$C$32,2,FALSE),0) -> 0.6 | C26: =$A$26*$B$26 -> 0 | D26: Mini Brioche ou Pão de Açucar
A27: =$C$6*0.2 -> 0 | B27: =IFERROR(VLOOKUP(D27,PREÇOS!$B$2:$C$32,2,FALSE),0) -> 0.5 | C27: =$A$27*$B$27 -> 0 | D27: Mini Bisnaguinha
A28: =$C$6*0.1 -> 0 | B28: =IFERROR(VLOOKUP(D28,PREÇOS!$B$2:$C$32,2,FALSE),0) -> 0.75 | C28: =$A$28*$B$28 -> 0 | D28: Mini Pão de coco
A29: =$C$6*0.1 -> 0 | B29: =IFERROR(VLOOKUP(D29,PREÇOS!$B$2:$C$32,2,FALSE),0) -> 0.6 | C29: =$A$29*$B$29 -> 0 | D29: Mini Pão doce
A30: =$C$6*0.2 -> 0 | B30: =IFERROR(VLOOKUP(D30,PREÇOS!$B$2:$C$32,2,FALSE),0) -> 0.8 | C30: =$A$30*$B$30 -> 0 | D30: Mini Donuts
A31: =$C$6*0.2 -> 0 | B31: =IFERROR(VLOOKUP(D31,PREÇOS!$B$2:$C$32,2,FALSE),0) -> 0.8 | C31: =$A$31*$B$31 -> 0 | D31: Mini Sonho
A32: =$C$6*0.2 -> 0 | B32: =IFERROR(VLOOKUP(D32,PREÇOS!$B$2:$C$32,2,FALSE),0) -> 0.85 | C32: =$A$32*$B$32 -> 0 | D32: Mini cookies
D33: FOLHADOS
A34: =$C$6*0.7 -> 0 | B34: =IFERROR(VLOOKUP(D34,PREÇOS!$B$2:$C$32,2,FALSE),0) -> 1.6 | C34: =$A$34*$B$34 -> 0 | D34: Mini Croissant
A35: =$C$6*0.5 -> 0 | B35: =IFERROR(VLOOKUP(D35,PREÇOS!$B$2:$C$32,2,FALSE),0) -> 1.8 | C35: =$A$35*$B$35 -> 0 | D35: Mini Pão de Chocolate
A36: =$C$6*0.5 -> 0 | B36: =IFERROR(VLOOKUP(D36,PREÇOS!$B$2:$C$32,2,FALSE),0) -> 0.95 | C36: =$A$36*$B$36 -> 0 | D36: Mini Folhado Salgado
A38: Total: | C38: =SUM(C9:C37) -> 0
A40: Produtos Volantes
A41: PAX | C41: 0 | D41: PADARIA
A42: unidades | D42: Pães salgados e doces
A43: =$C$41*0.7 -> 0 | B43: =IFERROR(VLOOKUP(D43,PREÇOS!$B$2:$C$32,2,FALSE),0) -> 0.63 | C43: =$A$43*$B$43 -> 0 | D43: Pão de queijo
A44: =$C$41*0.3 -> 0 | B44: =IFERROR(VLOOKUP(D44,PREÇOS!$B$2:$C$32,2,FALSE),0) -> 0.95 | C44: =$A$44*$B$44 -> 0 | D44: Folhado Salgado
...

Sheet DIA 10
A1: HOTEL NANNAI MURO ALTO
A2: PADARIA / CONFEITARIA
A4: PRODUÇÃO | B4: Dia: 10/06/2026
A5: RESTAURANTE NANNAI
A6: PAX | C6: 0 | D6: PADARIA | F6: ATENÇÃO ALTERAR SOMENTE EM VERMELHO, ALTERAR SOMENTE O NUMERO DE PESSOAS PAX
A8: unidades | B8: VALOR | C8: TOTAL | D8: PÃES SALGADOS
A9: =$C$6*0.9 -> 0 | B9: =IFERROR(VLOOKUP(D9,PREÇOS!$B$2:$C$32,2,FALSE),0) -> 0.4 | C9: =$A$9*$B$9 -> 0 | D9: Mini Pão Francês
A10: =$C$6*0.2 -> 0 | B10: =IFERROR(VLOOKUP(D10,PREÇOS!$B$2:$C$32,2,FALSE),0) -> 0.6 | C10: =$A$10*$B$10 -> 0 | D10: Mini Pão Integral
A11: =$C$6*0.2 -> 0 | B11: =IFERROR(VLOOKUP(D11,PREÇOS!$B$2:$C$32,2,FALSE),0) -> 0.8 | C11: =$A$11*$B$11 -> 0 | D11: Mini Australiano
A12: =$C$6*0.2 -> 0 | B12: =IFERROR(VLOOKUP(D12,PREÇOS!$B$2:$C$32,2,FALSE),0) -> 0.45 | C12: =$A$12*$B$12 -> 0 | D12: Mini Pão Gergilim
A13: =$C$6*0.2 -> 0 | B13: =IFERROR(VLOOKUP(D13,PREÇOS!$B$2:$C$32,2,FALSE),0) -> 0 | C13: =$A$13*$B$13 -> 0 | D13: Mini Pão de Milho ou
A14: =$C$6*0.1 -> 0 | B14: =IFERROR(VLOOKUP(D14,PREÇOS!$B$2:$C$32,2,FALSE),0) -> 0 | C14: =$A$14*$B$14 -> 0 | D14: Mini Baguete Rustica
A15: =$C$6*0.2 -> 0 | B15: =IFERROR(VLOOKUP(D15,PREÇOS!$B$2:$C$32,2,FALSE),0) -> 0.8 | C15: =$A$15*$B$15 -> 0 | D15: Mini Pão Calabresa
A16: =$C$6*0.2 -> 0 | B16: =IFERROR(VLOOKUP(D16,PREÇOS!$B$2:$C$32,2,FALSE),0) -> 0.7 | C16: =$A$16*$B$16 -> 0 | D16: Mini Pão Delicia recheado
A17: =$C$6*0.01 -> 0 | B17: =IFERROR(VLOOKUP(D17,PREÇOS!$B$2:$C$32,2,FALSE),0) -> 1.55 | C17: =$A$17*$B$17 -> 0 | D17: Focaccia recheada
A18: =$C$6*0.3 -> 0 | B18: =IFERROR(VLOOKUP(D18,PREÇOS!$B$2:$C$32,2,FALSE),0) -> 0.4 | C18: =$A$18*$B$18 -> 0 | D18: Mini Tiger
A19: =$C$6*0.2 -> 0 | B19: =IFERROR(VLOOKUP(D19,PREÇOS!$B$2:$C$32,2,FALSE),0) -> 0.8 | C19: =$A$19*$B$19 -> 0 | D19: Mini Pão de Frios
A20: =$C$6*0.004 -> 0 | B20: =IFERROR(VLOOKUP(D20,PREÇOS!$B$2:$C$32,2,FALSE),0) -> 3 | C20: =$A$20*$B$20 -> 0 | D20: Pão de Forma integral
A21: =$C$6*0.009 -> 0 | B21: =IFERROR(VLOOKUP(D21,PREÇOS!$B$2:$C$32,2,FALSE),0) -> 2.8 | C21: =$A$21*$B$21 -> 0 | D21: Pão de forma Tradicional
A22: =$C$6*0.004 -> 0 | B22: =IFERROR(VLOOKUP(D22,PREÇOS!$B$2:$C$32,2,FALSE),0) -> 3 | C22: =$A$22*$B$22 -> 0 | D22: Pão de Forma Maritoso
A23: =$C$6*0.04 -> 0 | B23: =IFERROR(VLOOKUP(D23,PREÇOS!$B$2:$C$32,2,FALSE),0) -> 2.6 | C23: =$A$23*$B$23 -> 0 | D23: Baguete Francesa 300g
A24: =$C$6*0.04 -> 0 | B24: =IFERROR(VLOOKUP(D24,PREÇOS!$B$2:$C$32,2,FALSE),0) -> 3.8 | C24: =$A$24*$B$24 -> 0 | D24: Pães de Decoração Rustico
D25: PÃES DOCES
A26: =$C$6*0.2 -> 0 | B26: =IFERROR(VLOOKUP(D26,PREÇOS!$B$2:$C$32,2,FALSE),0) -> 0.6 | C26: =$A$26*$B$26 -> 0 | D26: Mini Brioche ou Pão de Açucar
A27: =$C$6*0.2 -> 0 | B27: =IFERROR(VLOOKUP(D27,PREÇOS!$B$2:$C$32,2,FALSE),0) -> 0.5 | C27: =$A$27*$B$27 -> 0 | D27: Mini Bisnaguinha
A28: =$C$6*0.1 -> 0 | B28: =IFERROR(VLOOKUP(D28,PREÇOS!$B$2:$C$32,2,FALSE),0) -> 0.75 | C28: =$A$28*$B$28 -> 0 | D28: Mini Pão de coco
A29: =$C$6*0.1 -> 0 | B29: =IFERROR(VLOOKUP(D29,PREÇOS!$B$2:$C$32,2,FALSE),0) -> 0.6 | C29: =$A$29*$B$29 -> 0 | D29: Mini Pão doce
A30: =$C$6*0.2 -> 0 | B30: =IFERROR(VLOOKUP(D30,PREÇOS!$B$2:$C$32,2,FALSE),0) -> 0.8 | C30: =$A$30*$B$30 -> 0 | D30: Mini Donuts
A31: =$C$6*0.2 -> 0 | B31: =IFERROR(VLOOKUP(D31,PREÇOS!$B$2:$C$32,2,FALSE),0) -> 0.8 | C31: =$A$31*$B$31 -> 0 | D31: Mini Sonho
A32: =$C$6*0.2 -> 0 | B32: =IFERROR(VLOOKUP(D32,PREÇOS!$B$2:$C$32,2,FALSE),0) -> 0.85 | C32: =$A$32*$B$32 -> 0 | D32: Mini cookies
D33: FOLHADOS
A34: =$C$6*0.7 -> 0 | B34: =IFERROR(VLOOKUP(D34,PREÇOS!$B$2:$C$32,2,FALSE),0) -> 1.6 | C34: =$A$34*$B$34 -> 0 | D34: Mini Croissant
A35: =$C$6*0.5 -> 0 | B35: =IFERROR(VLOOKUP(D35,PREÇOS!$B$2:$C$32,2,FALSE),0) -> 1.8 | C35: =$A$35*$B$35 -> 0 | D35: Mini Pão de Chocolate
A36: =$C$6*0.5 -> 0 | B36: =IFERROR(VLOOKUP(D36,PREÇOS!$B$2:$C$32,2,FALSE),0) -> 0.95 | C36: =$A$36*$B$36 -> 0 | D36: Mini Folhado Salgado
A38: Total: | C38: =SUM(C9:C37) -> 0
A40: Produtos Volantes
A41: PAX | C41: 0 | D41: PADARIA
A42: unidades | D42: Pães salgados e doces
A43: =$C$41*0.7 -> 0 | B43: =IFERROR(VLOOKUP(D43,PREÇOS!$B$2:$C$32,2,FALSE),0) -> 0.63 | C43: =$A$43*$B$43 -> 0 | D43: Pão de queijo
A44: =$C$41*0.3 -> 0 | B44: =IFERROR(VLOOKUP(D44,PREÇOS!$B$2:$C$32,2,FALSE),0) -> 0.95 | C44: =$A$44*$B$44 -> 0 | D44: Folhado Salgado
...

Sheet DIA 11
A1: HOTEL NANNAI MURO ALTO
A2: PADARIA / CONFEITARIA
A4: PRODUÇÃO | B4: Dia: 11/06/2026
A5: RESTAURANTE NANNAI
A6: PAX | C6: 0 | D6: PADARIA | F6: ATENÇÃO ALTERAR SOMENTE EM VERMELHO, ALTERAR SOMENTE O NUMERO DE PESSOAS PAX
A8: unidades | B8: VALOR | C8: TOTAL | D8: PÃES SALGADOS
A9: =$C$6*0.9 -> 0 | B9: =IFERROR(VLOOKUP(D9,PREÇOS!$B$2:$C$32,2,FALSE),0) -> 0.4 | C9: =$A$9*$B$9 -> 0 | D9: Mini Pão Francês
A10: =$C$6*0.2 -> 0 | B10: =IFERROR(VLOOKUP(D10,PREÇOS!$B$2:$C$32,2,FALSE),0) -> 0.6 | C10: =$A$10*$B$10 -> 0 | D10: Mini Pão Integral
A11: =$C$6*0.2 -> 0 | B11: =IFERROR(VLOOKUP(D11,PREÇOS!$B$2:$C$32,2,FALSE),0) -> 0.8 | C11: =$A$11*$B$11 -> 0 | D11: Mini Australiano
A12: =$C$6*0.2 -> 0 | B12: =IFERROR(VLOOKUP(D12,PREÇOS!$B$2:$C$32,2,FALSE),0) -> 0.45 | C12: =$A$12*$B$12 -> 0 | D12: Mini Pão Gergilim
A13: =$C$6*0.2 -> 0 | B13: =IFERROR(VLOOKUP(D13,PREÇOS!$B$2:$C$32,2,FALSE),0) -> 0 | C13: =$A$13*$B$13 -> 0 | D13: Mini Pão de Milho ou
A14: =$C$6*0.1 -> 0 | B14: =IFERROR(VLOOKUP(D14,PREÇOS!$B$2:$C$32,2,FALSE),0) -> 0 | C14: =$A$14*$B$14 -> 0 | D14: Mini Baguete Rustica
A15: =$C$6*0.2 -> 0 | B15: =IFERROR(VLOOKUP(D15,PREÇOS!$B$2:$C$32,2,FALSE),0) -> 0.8 | C15: =$A$15*$B$15 -> 0 | D15: Mini Pão Calabresa
A16: =$C$6*0.2 -> 0 | B16: =IFERROR(VLOOKUP(D16,PREÇOS!$B$2:$C$32,2,FALSE),0) -> 0.7 | C16: =$A$16*$B$16 -> 0 | D16: Mini Pão Delicia recheado
A17: =$C$6*0.01 -> 0 | B17: =IFERROR(VLOOKUP(D17,PREÇOS!$B$2:$C$32,2,FALSE),0) -> 1.55 | C17: =$A$17*$B$17 -> 0 | D17: Focaccia recheada
A18: =$C$6*0.3 -> 0 | B18: =IFERROR(VLOOKUP(D18,PREÇOS!$B$2:$C$32,2,FALSE),0) -> 0.4 | C18: =$A$18*$B$18 -> 0 | D18: Mini Tiger
A19: =$C$6*0.2 -> 0 | B19: =IFERROR(VLOOKUP(D19,PREÇOS!$B$2:$C$32,2,FALSE),0) -> 0.8 | C19: =$A$19*$B$19 -> 0 | D19: Mini Pão de Frios
A20: =$C$6*0.004 -> 0 | B20: =IFERROR(VLOOKUP(D20,PREÇOS!$B$2:$C$32,2,FALSE),0) -> 3 | C20: =$A$20*$B$20 -> 0 | D20: Pão de Forma integral
A21: =$C$6*0.009 -> 0 | B21: =IFERROR(VLOOKUP(D21,PREÇOS!$B$2:$C$32,2,FALSE),0) -> 2.8 | C21: =$A$21*$B$21 -> 0 | D21: Pão de forma Tradicional
A22: =$C$6*0.004 -> 0 | B22: =IFERROR(VLOOKUP(D22,PREÇOS!$B$2:$C$32,2,FALSE),0) -> 3 | C22: =$A$22*$B$22 -> 0 | D22: Pão de Forma Maritoso
A23: =$C$6*0.04 -> 0 | B23: =IFERROR(VLOOKUP(D23,PREÇOS!$B$2:$C$32,2,FALSE),0) -> 2.6 | C23: =$A$23*$B$23 -> 0 | D23: Baguete Francesa 300g
A24: =$C$6*0.04 -> 0 | B24: =IFERROR(VLOOKUP(D24,PREÇOS!$B$2:$C$32,2,FALSE),0) -> 3.8 | C24: =$A$24*$B$24 -> 0 | D24: Pães de Decoração Rustico
D25: PÃES DOCES
A26: =$C$6*0.2 -> 0 | B26: =IFERROR(VLOOKUP(D26,PREÇOS!$B$2:$C$32,2,FALSE),0) -> 0.6 | C26: =$A$26*$B$26 -> 0 | D26: Mini Brioche ou Pão de Açucar
A27: =$C$6*0.2 -> 0 | B27: =IFERROR(VLOOKUP(D27,PREÇOS!$B$2:$C$32,2,FALSE),0) -> 0.5 | C27: =$A$27*$B$27 -> 0 | D27: Mini Bisnaguinha
A28: =$C$6*0.1 -> 0 | B28: =IFERROR(VLOOKUP(D28,PREÇOS!$B$2:$C$32,2,FALSE),0) -> 0.75 | C28: =$A$28*$B$28 -> 0 | D28: Mini Pão de coco
A29: =$C$6*0.1 -> 0 | B29: =IFERROR(VLOOKUP(D29,PREÇOS!$B$2:$C$32,2,FALSE),0) -> 0.6 | C29: =$A$29*$B$29 -> 0 | D29: Mini Pão doce
A30: =$C$6*0.2 -> 0 | B30: =IFERROR(VLOOKUP(D30,PREÇOS!$B$2:$C$32,2,FALSE),0) -> 0.8 | C30: =$A$30*$B$30 -> 0 | D30: Mini Donuts
A31: =$C$6*0.2 -> 0 | B31: =IFERROR(VLOOKUP(D31,PREÇOS!$B$2:$C$32,2,FALSE),0) -> 0.8 | C31: =$A$31*$B$31 -> 0 | D31: Mini Sonho
A32: =$C$6*0.2 -> 0 | B32: =IFERROR(VLOOKUP(D32,PREÇOS!$B$2:$C$32,2,FALSE),0) -> 0.85 | C32: =$A$32*$B$32 -> 0 | D32: Mini cookies
D33: FOLHADOS
A34: =$C$6*0.7 -> 0 | B34: =IFERROR(VLOOKUP(D34,PREÇOS!$B$2:$C$32,2,FALSE),0) -> 1.6 | C34: =$A$34*$B$34 -> 0 | D34: Mini Croissant
A35: =$C$6*0.5 -> 0 | B35: =IFERROR(VLOOKUP(D35,PREÇOS!$B$2:$C$32,2,FALSE),0) -> 1.8 | C35: =$A$35*$B$35 -> 0 | D35: Mini Pão de Chocolate
A36: =$C$6*0.5 -> 0 | B36: =IFERROR(VLOOKUP(D36,PREÇOS!$B$2:$C$32,2,FALSE),0) -> 0.95 | C36: =$A$36*$B$36 -> 0 | D36: Mini Folhado Salgado
A38: Total: | C38: =SUM(C9:C37) -> 0
A40: Produtos Volantes
A41: PAX | C41: 0 | D41: PADARIA
A42: unidades | D42: Pães salgados e doces
A43: =$C$41*0.7 -> 0 | B43: =IFERROR(VLOOKUP(D43,PREÇOS!$B$2:$C$32,2,FALSE),0) -> 0.63 | C43: =$A$43*$B$43 -> 0 | D43: Pão de queijo
A44: =$C$41*0.3 -> 0 | B44: =IFERROR(VLOOKUP(D44,PREÇOS!$B$2:$C$32,2,FALSE),0) -> 0.95 | C44: =$A$44*$B$44 -> 0 | D44: Folhado Salgado
...

Sheet DIA 12
A1: HOTEL NANNAI MURO ALTO
A2: PADARIA / CONFEITARIA
A4: PRODUÇÃO | B4: Dia: 12/06/2026
A5: RESTAURANTE NANNAI
A6: PAX | C6: 0 | D6: PADARIA | F6: ATENÇÃO ALTERAR SOMENTE EM VERMELHO, ALTERAR SOMENTE O NUMERO DE PESSOAS PAX
A8: unidades | B8: VALOR | C8: TOTAL | D8: PÃES SALGADOS
A9: =$C$6*0.9 -> 0 | B9: =IFERROR(VLOOKUP(D9,PREÇOS!$B$2:$C$32,2,FALSE),0) -> 0.4 | C9: =$A$9*$B$9 -> 0 | D9: Mini Pão Francês
A10: =$C$6*0.2 -> 0 | B10: =IFERROR(VLOOKUP(D10,PREÇOS!$B$2:$C$32,2,FALSE),0) -> 0.6 | C10: =$A$10*$B$10 -> 0 | D10: Mini Pão Integral
A11: =$C$6*0.2 -> 0 | B11: =IFERROR(VLOOKUP(D11,PREÇOS!$B$2:$C$32,2,FALSE),0) -> 0.8 | C11: =$A$11*$B$11 -> 0 | D11: Mini Australiano
A12: =$C$6*0.2 -> 0 | B12: =IFERROR(VLOOKUP(D12,PREÇOS!$B$2:$C$32,2,FALSE),0) -> 0.45 | C12: =$A$12*$B$12 -> 0 | D12: Mini Pão Gergilim
A13: =$C$6*0.2 -> 0 | B13: =IFERROR(VLOOKUP(D13,PREÇOS!$B$2:$C$32,2,FALSE),0) -> 0 | C13: =$A$13*$B$13 -> 0 | D13: Mini Pão de Milho ou
A14: =$C$6*0.1 -> 0 | B14: =IFERROR(VLOOKUP(D14,PREÇOS!$B$2:$C$32,2,FALSE),0) -> 0 | C14: =$A$14*$B$14 -> 0 | D14: Mini Baguete Rustica
A15: =$C$6*0.2 -> 0 | B15: =IFERROR(VLOOKUP(D15,PREÇOS!$B$2:$C$32,2,FALSE),0) -> 0.8 | C15: =$A$15*$B$15 -> 0 | D15: Mini Pão Calabresa
A16: =$C$6*0.2 -> 0 | B16: =IFERROR(VLOOKUP(D16,PREÇOS!$B$2:$C$32,2,FALSE),0) -> 0.7 | C16: =$A$16*$B$16 -> 0 | D16: Mini Pão Delicia recheado
A17: =$C$6*0.01 -> 0 | B17: =IFERROR(VLOOKUP(D17,PREÇOS!$B$2:$C$32,2,FALSE),0) -> 1.55 | C17: =$A$17*$B$17 -> 0 | D17: Focaccia recheada
A18: =$C$6*0.3 -> 0 | B18: =IFERROR(VLOOKUP(D18,PREÇOS!$B$2:$C$32,2,FALSE),0) -> 0.4 | C18: =$A$18*$B$18 -> 0 | D18: Mini Tiger
A19: =$C$6*0.2 -> 0 | B19: =IFERROR(VLOOKUP(D19,PREÇOS!$B$2:$C$32,2,FALSE),0) -> 0.8 | C19: =$A$19*$B$19 -> 0 | D19: Mini Pão de Frios
A20: =$C$6*0.004 -> 0 | B20: =IFERROR(VLOOKUP(D20,PREÇOS!$B$2:$C$32,2,FALSE),0) -> 3 | C20: =$A$20*$B$20 -> 0 | D20: Pão de Forma integral
A21: =$C$6*0.009 -> 0 | B21: =IFERROR(VLOOKUP(D21,PREÇOS!$B$2:$C$32,2,FALSE),0) -> 2.8 | C21: =$A$21*$B$21 -> 0 | D21: Pão de forma Tradicional
A22: =$C$6*0.004 -> 0 | B22: =IFERROR(VLOOKUP(D22,PREÇOS!$B$2:$C$32,2,FALSE),0) -> 3 | C22: =$A$22*$B$22 -> 0 | D22: Pão de Forma Maritoso
A23: =$C$6*0.04 -> 0 | B23: =IFERROR(VLOOKUP(D23,PREÇOS!$B$2:$C$32,2,FALSE),0) -> 2.6 | C23: =$A$23*$B$23 -> 0 | D23: Baguete Francesa 300g
A24: =$C$6*0.04 -> 0 | B24: =IFERROR(VLOOKUP(D24,PREÇOS!$B$2:$C$32,2,FALSE),0) -> 3.8 | C24: =$A$24*$B$24 -> 0 | D24: Pães de Decoração Rustico
D25: PÃES DOCES
A26: =$C$6*0.2 -> 0 | B26: =IFERROR(VLOOKUP(D26,PREÇOS!$B$2:$C$32,2,FALSE),0) -> 0.6 | C26: =$A$26*$B$26 -> 0 | D26: Mini Brioche ou Pão de Açucar
A27: =$C$6*0.2 -> 0 | B27: =IFERROR(VLOOKUP(D27,PREÇOS!$B$2:$C$32,2,FALSE),0) -> 0.5 | C27: =$A$27*$B$27 -> 0 | D27: Mini Bisnaguinha
A28: =$C$6*0.1 -> 0 | B28: =IFERROR(VLOOKUP(D28,PREÇOS!$B$2:$C$32,2,FALSE),0) -> 0.75 | C28: =$A$28*$B$28 -> 0 | D28: Mini Pão de coco
A29: =$C$6*0.1 -> 0 | B29: =IFERROR(VLOOKUP(D29,PREÇOS!$B$2:$C$32,2,FALSE),0) -> 0.6 | C29: =$A$29*$B$29 -> 0 | D29: Mini Pão doce
A30: =$C$6*0.2 -> 0 | B30: =IFERROR(VLOOKUP(D30,PREÇOS!$B$2:$C$32,2,FALSE),0) -> 0.8 | C30: =$A$30*$B$30 -> 0 | D30: Mini Donuts
A31: =$C$6*0.2 -> 0 | B31: =IFERROR(VLOOKUP(D31,PREÇOS!$B$2:$C$32,2,FALSE),0) -> 0.8 | C31: =$A$31*$B$31 -> 0 | D31: Mini Sonho
A32: =$C$6*0.2 -> 0 | B32: =IFERROR(VLOOKUP(D32,PREÇOS!$B$2:$C$32,2,FALSE),0) -> 0.85 | C32: =$A$32*$B$32 -> 0 | D32: Mini cookies
D33: FOLHADOS
A34: =$C$6*0.7 -> 0 | B34: =IFERROR(VLOOKUP(D34,PREÇOS!$B$2:$C$32,2,FALSE),0) -> 1.6 | C34: =$A$34*$B$34 -> 0 | D34: Mini Croissant
A35: =$C$6*0.5 -> 0 | B35: =IFERROR(VLOOKUP(D35,PREÇOS!$B$2:$C$32,2,FALSE),0) -> 1.8 | C35: =$A$35*$B$35 -> 0 | D35: Mini Pão de Chocolate
A36: =$C$6*0.5 -> 0 | B36: =IFERROR(VLOOKUP(D36,PREÇOS!$B$2:$C$32,2,FALSE),0) -> 0.95 | C36: =$A$36*$B$36 -> 0 | D36: Mini Folhado Salgado
A38: Total: | C38: =SUM(C9:C37) -> 0
A40: Produtos Volantes
A41: PAX | C41: 0 | D41: PADARIA
A42: unidades | D42: Pães salgados e doces
A43: =$C$41*0.7 -> 0 | B43: =IFERROR(VLOOKUP(D43,PREÇOS!$B$2:$C$32,2,FALSE),0) -> 0.63 | C43: =$A$43*$B$43 -> 0 | D43: Pão de queijo
A44: =$C$41*0.3 -> 0 | B44: =IFERROR(VLOOKUP(D44,PREÇOS!$B$2:$C$32,2,FALSE),0) -> 0.95 | C44: =$A$44*$B$44 -> 0 | D44: Folhado Salgado
...

Sheet DIA 13
A1: HOTEL NANNAI MURO ALTO
A2: PADARIA / CONFEITARIA
A4: PRODUÇÃO | B4: Dia: 13/06/2026
A5: RESTAURANTE NANNAI
A6: PAX | C6: 0 | D6: PADARIA | F6: ATENÇÃO ALTERAR SOMENTE EM VERMELHO, ALTERAR SOMENTE O NUMERO DE PESSOAS PAX
A8: unidades | B8: VALOR | C8: TOTAL | D8: PÃES SALGADOS
A9: =$C$6*0.9 -> 0 | B9: =IFERROR(VLOOKUP(D9,PREÇOS!$B$2:$C$32,2,FALSE),0) -> 0.4 | C9: =$A$9*$B$9 -> 0 | D9: Mini Pão Francês
A10: =$C$6*0.2 -> 0 | B10: =IFERROR(VLOOKUP(D10,PREÇOS!$B$2:$C$32,2,FALSE),0) -> 0.6 | C10: =$A$10*$B$10 -> 0 | D10: Mini Pão Integral
A11: =$C$6*0.2 -> 0 | B11: =IFERROR(VLOOKUP(D11,PREÇOS!$B$2:$C$32,2,FALSE),0) -> 0.8 | C11: =$A$11*$B$11 -> 0 | D11: Mini Australiano
A12: =$C$6*0.2 -> 0 | B12: =IFERROR(VLOOKUP(D12,PREÇOS!$B$2:$C$32,2,FALSE),0) -> 0.45 | C12: =$A$12*$B$12 -> 0 | D12: Mini Pão Gergilim
A13: =$C$6*0.2 -> 0 | B13: =IFERROR(VLOOKUP(D13,PREÇOS!$B$2:$C$32,2,FALSE),0) -> 0 | C13: =$A$13*$B$13 -> 0 | D13: Mini Pão de Milho ou
A14: =$C$6*0.1 -> 0 | B14: =IFERROR(VLOOKUP(D14,PREÇOS!$B$2:$C$32,2,FALSE),0) -> 0 | C14: =$A$14*$B$14 -> 0 | D14: Mini Baguete Rustica
A15: =$C$6*0.2 -> 0 | B15: =IFERROR(VLOOKUP(D15,PREÇOS!$B$2:$C$32,2,FALSE),0) -> 0.8 | C15: =$A$15*$B$15 -> 0 | D15: Mini Pão Calabresa
A16: =$C$6*0.2 -> 0 | B16: =IFERROR(VLOOKUP(D16,PREÇOS!$B$2:$C$32,2,FALSE),0) -> 0.7 | C16: =$A$16*$B$16 -> 0 | D16: Mini Pão Delicia recheado
A17: =$C$6*0.01 -> 0 | B17: =IFERROR(VLOOKUP(D17,PREÇOS!$B$2:$C$32,2,FALSE),0) -> 1.55 | C17: =$A$17*$B$17 -> 0 | D17: Focaccia recheada
A18: =$C$6*0.3 -> 0 | B18: =IFERROR(VLOOKUP(D18,PREÇOS!$B$2:$C$32,2,FALSE),0) -> 0.4 | C18: =$A$18*$B$18 -> 0 | D18: Mini Tiger
A19: =$C$6*0.2 -> 0 | B19: =IFERROR(VLOOKUP(D19,PREÇOS!$B$2:$C$32,2,FALSE),0) -> 0.8 | C19: =$A$19*$B$19 -> 0 | D19: Mini Pão de Frios
A20: =$C$6*0.004 -> 0 | B20: =IFERROR(VLOOKUP(D20,PREÇOS!$B$2:$C$32,2,FALSE),0) -> 3 | C20: =$A$20*$B$20 -> 0 | D20: Pão de Forma integral
A21: =$C$6*0.009 -> 0 | B21: =IFERROR(VLOOKUP(D21,PREÇOS!$B$2:$C$32,2,FALSE),0) -> 2.8 | C21: =$A$21*$B$21 -> 0 | D21: Pão de forma Tradicional
A22: =$C$6*0.004 -> 0 | B22: =IFERROR(VLOOKUP(D22,PREÇOS!$B$2:$C$32,2,FALSE),0) -> 3 | C22: =$A$22*$B$22 -> 0 | D22: Pão de Forma Maritoso
A23: =$C$6*0.04 -> 0 | B23: =IFERROR(VLOOKUP(D23,PREÇOS!$B$2:$C$32,2,FALSE),0) -> 2.6 | C23: =$A$23*$B$23 -> 0 | D23: Baguete Francesa 300g
A24: =$C$6*0.04 -> 0 | B24: =IFERROR(VLOOKUP(D24,PREÇOS!$B$2:$C$32,2,FALSE),0) -> 3.8 | C24: =$A$24*$B$24 -> 0 | D24: Pães de Decoração Rustico
D25: PÃES DOCES
A26: =$C$6*0.2 -> 0 | B26: =IFERROR(VLOOKUP(D26,PREÇOS!$B$2:$C$32,2,FALSE),0) -> 0.6 | C26: =$A$26*$B$26 -> 0 | D26: Mini Brioche ou Pão de Açucar
A27: =$C$6*0.2 -> 0 | B27: =IFERROR(VLOOKUP(D27,PREÇOS!$B$2:$C$32,2,FALSE),0) -> 0.5 | C27: =$A$27*$B$27 -> 0 | D27: Mini Bisnaguinha
A28: =$C$6*0.1 -> 0 | B28: =IFERROR(VLOOKUP(D28,PREÇOS!$B$2:$C$32,2,FALSE),0) -> 0.75 | C28: =$A$28*$B$28 -> 0 | D28: Mini Pão de coco
A29: =$C$6*0.1 -> 0 | B29: =IFERROR(VLOOKUP(D29,PREÇOS!$B$2:$C$32,2,FALSE),0) -> 0.6 | C29: =$A$29*$B$29 -> 0 | D29: Mini Pão doce
A30: =$C$6*0.2 -> 0 | B30: =IFERROR(VLOOKUP(D30,PREÇOS!$B$2:$C$32,2,FALSE),0) -> 0.8 | C30: =$A$30*$B$30 -> 0 | D30: Mini Donuts
A31: =$C$6*0.2 -> 0 | B31: =IFERROR(VLOOKUP(D31,PREÇOS!$B$2:$C$32,2,FALSE),0) -> 0.8 | C31: =$A$31*$B$31 -> 0 | D31: Mini Sonho
A32: =$C$6*0.2 -> 0 | B32: =IFERROR(VLOOKUP(D32,PREÇOS!$B$2:$C$32,2,FALSE),0) -> 0.85 | C32: =$A$32*$B$32 -> 0 | D32: Mini cookies
D33: FOLHADOS
A34: =$C$6*0.7 -> 0 | B34: =IFERROR(VLOOKUP(D34,PREÇOS!$B$2:$C$32,2,FALSE),0) -> 1.6 | C34: =$A$34*$B$34 -> 0 | D34: Mini Croissant
A35: =$C$6*0.5 -> 0 | B35: =IFERROR(VLOOKUP(D35,PREÇOS!$B$2:$C$32,2,FALSE),0) -> 1.8 | C35: =$A$35*$B$35 -> 0 | D35: Mini Pão de Chocolate
A36: =$C$6*0.5 -> 0 | B36: =IFERROR(VLOOKUP(D36,PREÇOS!$B$2:$C$32,2,FALSE),0) -> 0.95 | C36: =$A$36*$B$36 -> 0 | D36: Mini Folhado Salgado
A38: Total: | C38: =SUM(C9:C37) -> 0
A40: Produtos Volantes
A41: PAX | C41: 0 | D41: PADARIA
A42: unidades | D42: Pães salgados e doces
A43: =$C$41*0.7 -> 0 | B43: =IFERROR(VLOOKUP(D43,PREÇOS!$B$2:$C$32,2,FALSE),0) -> 0.63 | C43: =$A$43*$B$43 -> 0 | D43: Pão de queijo
A44: =$C$41*0.3 -> 0 | B44: =IFERROR(VLOOKUP(D44,PREÇOS!$B$2:$C$32,2,FALSE),0) -> 0.95 | C44: =$A$44*$B$44 -> 0 | D44: Folhado Salgado
...

Sheet DIA 14
A1: HOTEL NANNAI MURO ALTO
A2: PADARIA / CONFEITARIA
A4: PRODUÇÃO | B4: Dia: 14/06/2026
A5: RESTAURANTE NANNAI
A6: PAX | C6: 0 | D6: PADARIA | F6: ATENÇÃO ALTERAR SOMENTE EM VERMELHO, ALTERAR SOMENTE O NUMERO DE PESSOAS PAX
A8: unidades | B8: VALOR | C8: TOTAL | D8: PÃES SALGADOS
A9: =$C$6*0.9 -> 0 | B9: =IFERROR(VLOOKUP(D9,PREÇOS!$B$2:$C$32,2,FALSE),0) -> 0.4 | C9: =$A$9*$B$9 -> 0 | D9: Mini Pão Francês
A10: =$C$6*0.2 -> 0 | B10: =IFERROR(VLOOKUP(D10,PREÇOS!$B$2:$C$32,2,FALSE),0) -> 0.6 | C10: =$A$10*$B$10 -> 0 | D10: Mini Pão Integral
A11: =$C$6*0.2 -> 0 | B11: =IFERROR(VLOOKUP(D11,PREÇOS!$B$2:$C$32,2,FALSE),0) -> 0.8 | C11: =$A$11*$B$11 -> 0 | D11: Mini Australiano
A12: =$C$6*0.2 -> 0 | B12: =IFERROR(VLOOKUP(D12,PREÇOS!$B$2:$C$32,2,FALSE),0) -> 0.45 | C12: =$A$12*$B$12 -> 0 | D12: Mini Pão Gergilim
A13: =$C$6*0.2 -> 0 | B13: =IFERROR(VLOOKUP(D13,PREÇOS!$B$2:$C$32,2,FALSE),0) -> 0 | C13: =$A$13*$B$13 -> 0 | D13: Mini Pão de Milho ou
A14: =$C$6*0.1 -> 0 | B14: =IFERROR(VLOOKUP(D14,PREÇOS!$B$2:$C$32,2,FALSE),0) -> 0 | C14: =$A$14*$B$14 -> 0 | D14: Mini Baguete Rustica
A15: =$C$6*0.2 -> 0 | B15: =IFERROR(VLOOKUP(D15,PREÇOS!$B$2:$C$32,2,FALSE),0) -> 0.8 | C15: =$A$15*$B$15 -> 0 | D15: Mini Pão Calabresa
A16: =$C$6*0.2 -> 0 | B16: =IFERROR(VLOOKUP(D16,PREÇOS!$B$2:$C$32,2,FALSE),0) -> 0.7 | C16: =$A$16*$B$16 -> 0 | D16: Mini Pão Delicia recheado
A17: =$C$6*0.01 -> 0 | B17: =IFERROR(VLOOKUP(D17,PREÇOS!$B$2:$C$32,2,FALSE),0) -> 1.55 | C17: =$A$17*$B$17 -> 0 | D17: Focaccia recheada
A18: =$C$6*0.3 -> 0 | B18: =IFERROR(VLOOKUP(D18,PREÇOS!$B$2:$C$32,2,FALSE),0) -> 0.4 | C18: =$A$18*$B$18 -> 0 | D18: Mini Tiger
A19: =$C$6*0.2 -> 0 | B19: =IFERROR(VLOOKUP(D19,PREÇOS!$B$2:$C$32,2,FALSE),0) -> 0.8 | C19: =$A$19*$B$19 -> 0 | D19: Mini Pão de Frios
A20: =$C$6*0.004 -> 0 | B20: =IFERROR(VLOOKUP(D20,PREÇOS!$B$2:$C$32,2,FALSE),0) -> 3 | C20: =$A$20*$B$20 -> 0 | D20: Pão de Forma integral
A21: =$C$6*0.009 -> 0 | B21: =IFERROR(VLOOKUP(D21,PREÇOS!$B$2:$C$32,2,FALSE),0) -> 2.8 | C21: =$A$21*$B$21 -> 0 | D21: Pão de forma Tradicional
A22: =$C$6*0.004 -> 0 | B22: =IFERROR(VLOOKUP(D22,PREÇOS!$B$2:$C$32,2,FALSE),0) -> 3 | C22: =$A$22*$B$22 -> 0 | D22: Pão de Forma Maritoso
A23: =$C$6*0.04 -> 0 | B23: =IFERROR(VLOOKUP(D23,PREÇOS!$B$2:$C$32,2,FALSE),0) -> 2.6 | C23: =$A$23*$B$23 -> 0 | D23: Baguete Francesa 300g
A24: =$C$6*0.04 -> 0 | B24: =IFERROR(VLOOKUP(D24,PREÇOS!$B$2:$C$32,2,FALSE),0) -> 3.8 | C24: =$A$24*$B$24 -> 0 | D24: Pães de Decoração Rustico
D25: PÃES DOCES
A26: =$C$6*0.2 -> 0 | B26: =IFERROR(VLOOKUP(D26,PREÇOS!$B$2:$C$32,2,FALSE),0) -> 0.6 | C26: =$A$26*$B$26 -> 0 | D26: Mini Brioche ou Pão de Açucar
A27: =$C$6*0.2 -> 0 | B27: =IFERROR(VLOOKUP(D27,PREÇOS!$B$2:$C$32,2,FALSE),0) -> 0.5 | C27: =$A$27*$B$27 -> 0 | D27: Mini Bisnaguinha
A28: =$C$6*0.1 -> 0 | B28: =IFERROR(VLOOKUP(D28,PREÇOS!$B$2:$C$32,2,FALSE),0) -> 0.75 | C28: =$A$28*$B$28 -> 0 | D28: Mini Pão de coco
A29: =$C$6*0.1 -> 0 | B29: =IFERROR(VLOOKUP(D29,PREÇOS!$B$2:$C$32,2,FALSE),0) -> 0.6 | C29: =$A$29*$B$29 -> 0 | D29: Mini Pão doce
A30: =$C$6*0.2 -> 0 | B30: =IFERROR(VLOOKUP(D30,PREÇOS!$B$2:$C$32,2,FALSE),0) -> 0.8 | C30: =$A$30*$B$30 -> 0 | D30: Mini Donuts
A31: =$C$6*0.2 -> 0 | B31: =IFERROR(VLOOKUP(D31,PREÇOS!$B$2:$C$32,2,FALSE),0) -> 0.8 | C31: =$A$31*$B$31 -> 0 | D31: Mini Sonho
A32: =$C$6*0.2 -> 0 | B32: =IFERROR(VLOOKUP(D32,PREÇOS!$B$2:$C$32,2,FALSE),0) -> 0.85 | C32: =$A$32*$B$32 -> 0 | D32: Mini cookies
D33: FOLHADOS
A34: =$C$6*0.7 -> 0 | B34: =IFERROR(VLOOKUP(D34,PREÇOS!$B$2:$C$32,2,FALSE),0) -> 1.6 | C34: =$A$34*$B$34 -> 0 | D34: Mini Croissant
